Workbook
Name ARA_Threshold: #REF!
Name ARA_Threshold: #REF!
Name ARA_Threshold: #REF!
Name ARP_Threshold: #REF!
Name ARP_Threshold: #REF!
Name ARP_Threshold: #REF!
Name att1st_12th: #REF!
Name att1st_12th: #REF!
Name att1st_12th: #REF!
Name cf: #REF!
Name cf: #REF!
Name cf: #REF!
Name cominf: #REF!
Name cominf: #REF!
Name cominf: #REF!
Name dcf_cof: #REF!
Name dcf_cof: #REF!
Name dcf_cof: #REF!
Name dpl: #REF!
Name dpl: #REF!
Name dpl: #REF!
Name L_CY_Beg: [1]Links!$F$1:$F$65536
Name L_CY_End: [1]Links!$J$1:$J$65536
Name L_PY_End: [1]Links!$K$1:$K$65536
Name L_RJE_Tot: [1]Links!$I$1:$I$65536
Name landarea: #REF!
Name landarea: #REF!
Name landarea: #REF!
Name Low_Cost_Flats___9_units_shops: '[2]SP, RW & SG.BU'!#REF!
Name Low_Cost_Flats___9_units_shops: '[2]SP, RW & SG.BU'!#REF!
Name Low_Cost_Flats___9_units_shops: '[2]SP, RW & SG.BU'!#REF!
Name ohworking: #REF!
Name ohworking: #REF!
Name ohworking: #REF!
Name pc1p: #REF!
Name pc1p: #REF!
Name pc1p: #REF!
Name pc2p: #REF!
Name pc2p: #REF!
Name pc2p: #REF!
Name pl8and4: #REF!
Name pl8and4: #REF!
Name pl8and4: #REF!
Name PLqtrly: #REF!
Name PLqtrly: #REF!
Name PLqtrly: #REF!
Name row: #REF!
Name row: #REF!
Name row: #REF!
Name rowrm: #REF!
Name rowrm: #REF!
Name rowrm: #REF!
Name S_AcctDes: #REF!
Name S_AcctDes: #REF!
Name S_AcctDes: #REF!
Name S_Adjust: #REF!
Name S_Adjust: #REF!
Name S_Adjust: #REF!
Name S_Adjust_GT: #REF!
Name S_Adjust_GT: #REF!

Sheet Jan-25
A5: 月费善款 收纳表/ Official Receipt Summary: | N5: 2025 年 1 月份 - HLB 05500129613
E6: 赞助的月份
E7: Payment for the month of | K7: 金额 Amount (RM)
A8: 日期 Date | B8: 收据编号 Official Receipt No | C8: 编号 No. | D8: 捐款人 姓名 Name | E8: START MONTH | F8: END MONTH | G8: REF. | K8: 现款 Cash | L8: 支票 Cheque | M8: 网上银行转账 Online Bank Transfer | N8: Bank-in Amount | O8: Bank-in Date | P8: 备注 Remark
A10: 01.01.2025 | B10: CHE 0001064 | C10: 106 | D10: 文渼渼 | E10: Nov-24 | F10: Dec-24 | G10: Nov-Dec-24 | H10: 2 | I10: 50 | J10: 100 | K10: 100.00 | P10: 122 | T10: 45536
A11: 01.01.2025 | B11: CHE 0001065 | C11: 106 | D11: 文渼渼 | E11: 45658 | F11: 45809 | G11: Jan-Jun-25 | H11: =DATEDIF(E11,F11,"M")+1 -> 6 | I11: 50 | J11: =H11*I11 -> 300 | K11: 300 | T11: 45566
A12: 01.01.2025 | B12: CHE 0001066 | C12: 214 | D12: 苏素镇 | E12: 45658 | F12: 45717 | G12: Jan-Mar-25 | H12: =DATEDIF(E12,F12,"M")+1 -> 3 | I12: 50 | J12: =H12*I12 -> 150 | K12: 150 | T12: 45597
A13: 01.01.2025 | B13: CHE 0001067 | C13: 177 | D13: 陈桂香 | E13: 45658 | F13: 45717 | G13: Jan-Mar-25 | H13: =DATEDIF(E13,F13,"M")+1 -> 3 | I13: 50 | J13: =H13*I13 -> 150 | K13: 150 | T13: 45627
A14: 03.01.2025 | B14: CHE 0001068 | C14: 90 | D14: 程秋萍 | E14: 45658 | F14: 45992 | G14: Jan-Dec-25 | H14: =DATEDIF(E14,F14,"M")+1 -> 12 | I14: 50 | J14: =H14*I14 -> 600 | K14: 600 | T14: 45658
A15: 03.01.2025 | B15: CHE 0001069 | C15: 192 | D15: 锺堉煒 | E15: 45658 | F15: 45992 | G15: Jan-Dec-25 | H15: =DATEDIF(E15,F15,"M")+1 -> 12 | I15: 50 | J15: =H15*I15 -> 600 | K15: 600 | T15: 45689
A16: 03.01.2025 | B16: CHE 0001070 | C16: 19 | D16: 廖秋华 | E16: 45658 | F16: 45748 | G16: Jan-Apr-25 | H16: =DATEDIF(E16,F16,"M")+1 -> 4 | I16: 50 | J16: =H16*I16 -> 200 | K16: 200 | T16: 45717
A17: 04.01.2025 | B17: CHE 0001071 | C17: 189 | D17: 张秀杏 | E17: 45658 | F17: 45992 | G17: Jan-Dec-25 | H17: =DATEDIF(E17,F17,"M")+1 -> 12 | I17: 50 | J17: =H17*I17 -> 600 | K17: 600 | N17: =SUM(K10:K17) -> 2600 | O17: 05.01.2025 | T17: 45748
A18: 06.01.2025 | B18: CHE 0001072 | C18: 97 | D18: 陈素秋 | E18: 45658 | F18: 45748 | G18: Jan-Apr-25 | H18: =DATEDIF(E18,F18,"M")+1 -> 4 | I18: 50 | J18: =H18*I18 -> 200 | K18: 200 | T18: 45778
A19: 06.01.2025 | B19: CHE 0001073 | C19: 71 | D19: 房丽珍 | E19: 45566 | F19: 45778 | G19: Oct-24-May-25 | H19: =DATEDIF(E19,F19,"M")+1 -> 8 | I19: 50 | J19: =H19*I19 -> 400 | K19: 400 | T19: 45809
A20: 06.01.2025 | B20: CHE 0001074 | C20: 36 | D20: 钱淑娟 | E20: 45658 | F20: 45992 | G20: Jan-Dec-25 | H20: =DATEDIF(E20,F20,"M")+1 -> 12 | I20: 50 | J20: =H20*I20 -> 600 | K20: 600 | T20: 45839
A21: 06.01.2025 | B21: CHE 0001075 | C21: 74 | D21: 黄得财 | E21: 45658 | F21: 45778 | G21: Jan-May-25 | H21: =DATEDIF(E21,F21,"M")+1 -> 5 | I21: 50 | J21: =H21*I21 -> 250 | K21: 250 | T21: 45870
A22: 07.01.2025 | B22: CHE 0001076 | C22: 126 | D22: 张凤 | E22: 45658 | F22: 45717 | G22: Jan-Mar-25 | H22: =DATEDIF(E22,F22,"M")+1 -> 3 | I22: 50 | J22: =H22*I22 -> 150 | K22: 150 | T22: 45901
A23: 08.01.2025 | B23: CHE 0001077 | C23: 4 | D23: 邹运金 | E23: 45658 | F23: 45689 | G23: Jan-Feb-25 | H23: =DATEDIF(E23,F23,"M")+1 -> 2 | I23: 50 | J23: =H23*I23 -> 100 | K23: 100 | T23: 45931
A24: 09.01.2025 | B24: CHE 0001078 | C24: 178 | D24: 颜美荭 | E24: 45658 | F24: 45689 | G24: Jan-Feb-25 | H24: =DATEDIF(E24,F24,"M")+1 -> 2 | I24: 50 | J24: =H24*I24 -> 100 | K24: 100 | T24: 45962
A25: 11.01.2025 | B25: CHE 0001079 | C25: 186 | D25: 刘玉云 | E25: 45658 | F25: 45689 | G25: Jan-Feb-25 | H25: =DATEDIF(E25,F25,"M")+1 -> 2 | I25: 50 | J25: =H25*I25 -> 100 | K25: 100 | T25: 45992
A26: 11.01.2025 | B26: CHE 0001080 | C26: 23 | D26: 罗彩云 | E26: 45658 | F26: 45809 | G26: Jan-Jun-25 | H26: =DATEDIF(E26,F26,"M")+1 -> 6 | I26: 50 | J26: =H26*I26 -> 300 | K26: 300 | T26: 46023
A27: 11.01.2025 | B27: CHE 0001081 | C27: 114 | D27: 刁修淋 | E27: 45658 | F27: 45689 | G27: Jan-Feb-25 | H27: =DATEDIF(E27,F27,"M")+1 -> 2 | I27: 50 | J27: =H27*I27 -> 100 | K27: 100 | N27: =SUM(K18:K27) -> 2300 | O27: 13.01.2025 | T27: 46054
A28: 12.01.2025 | B28: CHE 0001082 | C28: 42 | D28: 李俐祯 | E28: 45658 | F28: 45809 | G28: Jan-Jun-25 | H28: =DATEDIF(E28,F28,"M")+1 -> 6 | I28: 50 | J28: =H28*I28 -> 300 | K28: 300 | T28: 46082
A29: 13.01.2025 | B29: CHE 0001083 | C29: 208 | D29: 萧志伦 | E29: 45658 | F29: 45658 | G29: 45658 | H29: =DATEDIF(E29,F29,"M")+1 -> 1 | I29: 50 | J29: =H29*I29 -> 50 | K29: 50 | T29: 46113
A30: 14.01.2025 | B30: CHE 0001084 | C30: 99 | D30: 吴毓遴 | E30: 45658 | F30: 45689 | G30: Jan-Feb-25 | H30: =DATEDIF(E30,F30,"M")+1 -> 2 | I30: 50 | J30: =H30*I30 -> 100 | K30: 100 | T30: 46143
A31: 14.01.2025 | B31: CHE 0001085 | C31: 120 | D31: 王碧琳 | E31: 45658 | F31: 45992 | G31: Jan-Dec-25 | H31: =DATEDIF(E31,F31,"M")+1 -> 12 | I31: 50 | J31: =H31*I31 -> 600 | K31: 600 | T31: 46174
A32: 14.01.2025 | B32: CHE 0001086 | C32: 227 | D32: 丘桂盈 | E32: 45658 | F32: 45809 | G32: Jan-Jun-25 | H32: =DATEDIF(E32,F32,"M")+1 -> 6 | I32: 50 | J32: =H32*I32 -> 300 | K32: 300 | N32: =SUM(K28:K32) -> 1350 | O32: 22.01.2025 | T32: 46204
A33: 20.01.2025 | B33: CHE 0001087 | C33: 181 | D33: 陈金清 | E33: 45658 | F33: 45689 | G33: Jan-Feb-25 | H33: =DATEDIF(E33,F33,"M")+1 -> 2 | I33: 50 | J33: =H33*I33 -> 100 | K33: 100 | T33: 46235
A34: 20.01.2025 | B34: CHE 0001088 | C34: 73 | D34: 李宝明 | E34: 45658 | F34: 45748 | G34: Jan-Apr-25 | H34: =DATEDIF(E34,F34,"M")+1 -> 4 | I34: 50 | J34: =H34*I34 -> 200 | K34: 200 | T34: 46266
A35: 23.01.2025 | B35: CHE 0001089 | C35: 185 | D35: 羅梅瑂 | E35: 45658 | F35: 45689 | G35: Jan-Feb-25 | H35: =DATEDIF(E35,F35,"M")+1 -> 2 | I35: 50 | J35: =H35*I35 -> 100 | K35: 100 | N35: =SUM(K33:K35) -> 400 | O35: 28.01.2025 | T35: 46296
A36: 28.01.2025 | B36: CHE 0001090 | C36: 131 | D36: 王康芬 | E36: 45658 | F36: 45717 | G36: Jan-Mar-25 | H36: =DATEDIF(E36,F36,"M")+1 -> 3 | I36: 50 | J36: =H36*I36 -> 150 | K36: 150 | T36: 46327
A37: 29.01.2025 | B37: CHE 0001091 | C37: 3 | D37: Anna Justina | E37: 45717 | F37: 45809 | G37: Mar-Jun-25 | H37: =DATEDIF(E37,F37,"M")+1 -> 4 | I37: 50 | J37: =H37*I37 -> 200 | K37: 200 | T37: 46357
A38: 29.01.2025 | B38: CHE 0001092 | C38: 69 | D38: 卢锭伟 | E38: 45658 | F38: 45809 | G38: Jan-Jun-25 | H38: =DATEDIF(E38,F38,"M")+1 -> 6 | I38: 50 | J38: =H38*I38 -> 300 | K38: 300 | N38: =SUM(K36:K38) -> 650 | O38: 30.01.2025 | T38: 46388
A39: 29.01.2025 | B39: CHE 0001093 | C39: 178 | D39: 颜美荭 | E39: 45717 | F39: 45717 | G39: 45717 | H39: =DATEDIF(E39,F39,"M")+1 -> 1 | I39: 50 | J39: =H39*I39 -> 50 | K39: 50
A40: 29.01.2025 | B40: CHE 0001094 | C40: 11 | D40: 方玉芬 | E40: 45658 | F40: 45992 | G40: Jan-Dec-25 | H40: =DATEDIF(E40,F40,"M")+1 -> 12 | I40: 50 | J40: =H40*I40 -> 600 | K40: 600
A41: 29.01.2025 | B41: CHE 0001095 | C41: 127 | D41: 陈梅兰 | E41: 45658 | F41: 45992 | G41: Jan-Dec-25 | H41: =DATEDIF(E41,F41,"M")+1 -> 12 | I41: 50 | J41: =H41*I41 -> 600 | K41: 600
A42: 29.01.2025 | B42: CHE 0001096 | C42: 191 | D42: 锺鏸堬 | E42: 45658 | F42: 45992 | G42: Jan-Dec-25 | H42: =DATEDIF(E42,F42,"M")+1 -> 12 | I42: 50 | J42: =H42*I42 -> 600 | K42: 600
A43: 29.01.2025 | B43: CHE 0001097 | C43: 226 | D43: 锺镒壕 | E43: 45658 | F43: 45717 | G43: Jan-Mar-25 | H43: =DATEDIF(E43,F43,"M")+1 -> 3 | I43: 50 | J43: =H43*I43 -> 150 | K43: 150
A44: 29.01.2025 | B44: CHE 0001098 | C44: 170 | D44: 陈柔霓 | E44: 45658 | F44: 45689 | G44: Jan-Feb-25 | H44: =DATEDIF(E44,F44,"M")+1 -> 2 | I44: 50 | J44: =H44*I44 -> 100 | K44: 100 | N44: =SUM(K39:K44) -> 2100 | O44: 01.02.2025
A49: 01.01.2025 | B49: CHE0001039 | C49: 162 | D49: 方惠贤 | E49: 45658 | F49: 45689 | G49: Jan-Feb-25 | H49: =DATEDIF(E49,F49,"M")+1 -> 2 | I49: 50 | J49: =H49*I49 -> 100 | M49: 100 | O49: Book No.121 | P49: BT | Q49: Fong Fui Ying
...

Sheet Feb-25
A5: 月费善款 收纳表/ Official Receipt Summary: | N5: 2025 年 2 月份 - HLB 05500129613
E6: 赞助的月份
E7: Payment for the month of | K7: 金额 Amount (RM)
A8: 日期 Date | B8: 收据编号 Official Receipt No | C8: 编号 No. | D8: 捐款人 姓名 Name | E8: START MONTH | F8: END MONTH | G8: REF. | K8: 现款 Cash | L8: 支票 Cheque | M8: 网上银行转账 Online Bank Transfer | N8: Bank-in Amount | O8: Bank-in Date | P8: 备注 Remark
A10: 02.02.2025 | B10: CHE 0001099 | C10: 43 | D10: 林德成 | E10: 45658 | F10: 45717 | G10: Jan-Mar-25 | H10: =DATEDIF(E10,F10,"M")+1 -> 3 | I10: 50 | J10: =H10*I10 -> 150 | K10: 150 | P10: Book No.22/122 | W10: 45536
B11: CHE 0001100 | D11: cancel | W11: 45566
A12: 04.02.2025 | B12: CHE 0001101 | C12: 183 | D12: 郭丽诗 | E12: 45658 | F12: 45778 | G12: Jan-May-25 | H12: =DATEDIF(E12,F12,"M")+1 -> 5 | I12: 50 | J12: =H12*I12 -> 250 | K12: 250 | P12: Book No.23/123 | W12: 45597
A13: 05.02.2025 | B13: CHE 0001102 | C13: 103 | D13: 林采谚 | E13: 45658 | F13: 45748 | G13: Jan-Apr-25 | H13: =DATEDIF(E13,F13,"M")+1 -> 4 | I13: 50 | J13: =H13*I13 -> 200 | K13: 200 | W13: 45627
A14: 06.02.2025 | B14: CHE 0001103 | C14: 199 | D14: 叶翠芬 | E14: 45658 | F14: 45689 | G14: Jan-Feb-25 | H14: =DATEDIF(E14,F14,"M")+1 -> 2 | I14: 50 | J14: =H14*I14 -> 100 | K14: 100 | W14: 45658
A15: 06.02.2025 | B15: CHE 0001104 | C15: 92 | D15: 叶碧玉 | E15: 45658 | F15: 45992 | G15: Jan-Dec-25 | H15: =DATEDIF(E15,F15,"M")+1 -> 12 | I15: 50 | J15: =H15*I15 -> 600 | K15: 600 | W15: 45689
A16: 06.02.2025 | B16: CHE 0001105 | C16: 167 | D16: 罗紫纶 | E16: 45658 | F16: 45992 | G16: Jan-Dec-25 | H16: =DATEDIF(E16,F16,"M")+1 -> 12 | I16: 50 | J16: =H16*I16 -> 600 | K16: 600 | W16: 45717
A17: 08.02.2025 | B17: CHE 0001106 | C17: 54 | D17: 黄丽玲 | E17: 45689 | F17: 45717 | G17: Feb-Mar25 | H17: =DATEDIF(E17,F17,"M")+1 -> 2 | I17: 50 | J17: =H17*I17 -> 100 | K17: 100 | W17: 45748
A18: 08.02.2025 | B18: CHE 0001107 | C18: 184 | D18: 赖奕坊 | E18: 45689 | F18: 45689 | G18: 45689 | H18: =DATEDIF(E18,F18,"M")+1 -> 1 | I18: 50 | J18: =H18*I18 -> 50 | K18: 50 | N18: =SUM(K10:K18) -> 2050 | O18: 15.02.2025 | W18: 45778
A19: 10.02.2025 | B19: CHE 0001108 | C19: 168 | D19: 王秋蓉 | E19: 45658 | F19: 45689 | G19: Jan-Feb-25 | H19: =DATEDIF(E19,F19,"M")+1 -> 2 | I19: 50 | J19: =H19*I19 -> 100 | K19: 100 | W19: 45809
A20: 12.02.2025 | B20: CHE 0001109 | C20: 96 | D20: 余丽苹 | E20: 45658 | F20: 45809 | G20: Jan-Jun-25 | H20: =DATEDIF(E20,F20,"M")+1 -> 6 | I20: 50 | J20: =H20*I20 -> 300 | K20: 300 | W20: 45839
A21: 12.02.2025 | B21: CHE 0001110 | C21: 33 | D21: 房薇玲 | E21: 45658 | F21: 45809 | G21: Jan-Jun-25 | H21: =DATEDIF(E21,F21,"M")+1 -> 6 | I21: 50 | J21: =H21*I21 -> 300 | K21: 300 | W21: 45870
A22: 12.02.2025 | B22: CHE 0001111 | C22: 132 | D22: 陈杍䍿 | E22: 45717 | F22: 45748 | G22: Mar-Apr-25 | H22: =DATEDIF(E22,F22,"M")+1 -> 2 | I22: 50 | J22: =H22*I22 -> 100 | K22: 100 | W22: 45901
A23: 12.02.2025 | B23: CHE 0001112 | C23: 223 | D23: 黄莉珍 | E23: 45717 | F23: 45748 | G23: Mar-Apr-25 | H23: =DATEDIF(E23,F23,"M")+1 -> 2 | I23: 50 | J23: =H23*I23 -> 100 | K23: 100 | N23: =SUM(K19:K23) -> 900 | O23: 16.02.2025 | W23: 45931
A24: 16.2.2025 | B24: CHE 0001113 | C24: 148 | D24: 黄玉莲 | E24: 45658 | F24: 45992 | G24: Jan-Dec-25 | H24: =DATEDIF(E24,F24,"M")+1 -> 12 | I24: 50 | J24: =H24*I24 -> 600 | K24: 600 | W24: 45962
A25: 21.2.2025 | B25: CHE 0001114 | C25: 208 | D25: 苏志伦 | E25: 45689 | F25: 45689 | G25: 45689 | H25: =DATEDIF(E25,F25,"M")+1 -> 1 | I25: 50 | J25: =H25*I25 -> 50 | K25: 50 | W25: 45992
A26: 23.2.2025 | B26: CHE 0001115 | C26: 195 | D26: 田玉美 | E26: 45658 | F26: 45992 | G26: Jan-Dec-25 | H26: =DATEDIF(E26,F26,"M")+1 -> 12 | I26: 50 | J26: =H26*I26 -> 600 | K26: 600 | W26: 46023
A27: 27.2.2025 | B27: CHE 0001116 | C27: 229 | D27: 陈丽珍 | E27: 45717 | F27: 45748 | G27: Mar-Apr-25 | H27: =DATEDIF(E27,F27,"M")+1 -> 2 | I27: 50 | J27: =H27*I27 -> 100 | K27: 100 | W27: 46054
A28: 28.2.2025 | B28: CHE 0001117 | C28: 164 | D28: 梁佩仪 | E28: 45658 | F28: 45748 | G28: Jan-Apr-25 | H28: =DATEDIF(E28,F28,"M")+1 -> 4 | I28: 50 | J28: =H28*I28 -> 200 | K28: 200 | N28: =SUM(K24:K28) -> 1550 | O28: 04.03.2025 | P28: Book No.23/123 | W28: 46082
W29: 46113
W30: 46143
W31: 46174
W32: 46204
A33: 02.02.2025 | B33: CHE0001217 | C33: 160 | D33: 郑筱頵 | E33: 45717 | F33: 45992 | G33: Mar-Dec-25 | H33: =DATEDIF(E33,F33,"M")+1 -> 10 | I33: 50 | J33: =H33*I33 -> 500 | M33: 500 | O33: Book No.125 | P33: BT | Q33: Chang Sau Cheen | W33: 46235
A34: 03.02.2025 | B34: CHE0001218 | C34: 102 | D34: 戴川风 | E34: 45658 | F34: 45689 | G34: Jan-Feb-25 | H34: =DATEDIF(E34,F34,"M")+1 -> 2 | I34: 50 | J34: =H34*I34 -> 100 | M34: 100 | P34: ATM | W34: 46266
A35: 03.02.2025 | B35: CHE0001219 | C35: 116 | D35: 李薇薇 | E35: 45689 | F35: 45689 | G35: 45689 | H35: =DATEDIF(E35,F35,"M")+1 -> 1 | I35: 50 | J35: =H35*I35 -> 50 | M35: 50 | P35: BT | Q35: Lee Wei Wei | W35: 46296
A36: 03.02.2025 | B36: CHE0001220 | C36: 117 | D36: 张志文 | E36: 45689 | F36: 45689 | G36: 45689 | H36: =DATEDIF(E36,F36,"M")+1 -> 1 | I36: 50 | J36: =H36*I36 -> 50 | M36: 50 | P36: BT | Q36: Chong Chee Wen | W36: 46327
A37: 05.02.2025 | B37: CHE0001221 | C37: 52 | D37: 陈宝蓉 | E37: 45658 | F37: 45689 | G37: Jan-Feb-25 | H37: =DATEDIF(E37,F37,"M")+1 -> 2 | I37: 50 | J37: =H37*I37 -> 100 | M37: 100 | P37: BT | Q37: Tan Poh Yong | W37: 46357
A38: 07.02.2025 | B38: CHE0001222 | C38: 40 | D38: Hoo Mei Sing | E38: 45748 | F38: 45839 | G38: Apr-Jul25 | H38: =DATEDIF(E38,F38,"M")+1 -> 4 | I38: 50 | J38: =H38*I38 -> 200 | M38: 200 | P38: BT | Q38: Ho Mei Sing | W38: 46388
A39: 10.02.2025 | B39: CHE0001223 | C39: 6 | D39: 张婷奕 | E39: 45658 | F39: 45992 | G39: Jan-Dec-25 | H39: =DATEDIF(E39,F39,"M")+1 -> 12 | I39: 50 | J39: =H39*I39 -> 600 | M39: 600 | P39: BT | Q39: Chong Sue Mei
A40: 15.02.2025 | B40: CHE0001224 | C40: 212 | D40: 许愫苓 | E40: 45566 | F40: 45717 | G40: Oct-24-Mar-25 | H40: =DATEDIF(E40,F40,"M")+1 -> 6 | I40: 50 | J40: =H40*I40 -> 300 | M40: 300 | P40: BT | Q40: Khoo Su Chin
A41: 15.02.2025 | B41: CHE0001225 | C41: 25 | D41: 何艺寿 | E41: 45689 | F41: 46023 | G41: Feb-25-Jan-26 | H41: =DATEDIF(E41,F41,"M")+1 -> 12 | I41: 50 | J41: =H41*I41 -> 600 | M41: 600 | P41: BT | Q41: Hoo Yoke Saw
A42: 17.02.2025 | B42: CHE0001226 | C42: 24 | D42: 陈淑心 | E42: 45658 | F42: 45717 | G42: Jan-Mar-25 | H42: =DATEDIF(E42,F42,"M")+1 -> 3 | I42: 50 | J42: =H42*I42 -> 150 | M42: 150 | P42: BT | Q42: Chan Sook Ling
A43: 22.02.2025 | B43: CHE0001227 | C43: 137 | D43: 赖美珍 | E43: 45689 | F43: 45689 | G43: 45689 | H43: =DATEDIF(E43,F43,"M")+1 -> 1 | I43: 50 | J43: =H43*I43 -> 50 | M43: 50 | P43: ATM
A44: 28.02.2025 | B44: CHE0001228 | C44: 80 | D44: 黄淑芬 | E44: 45717 | F44: 45717 | G44: 45717 | H44: =DATEDIF(E44,F44,"M")+1 -> 1 | I44: 50 | J44: =H44*I44 -> 50 | M44: 50 | P44: BT | Q44: Wong Su Fong
A45: 28.02.2025 | B45: CHE0001229 | C45: 224 | D45: 黄文胜 | E45: 45717 | F45: 45717 | G45: 45717 | H45: =DATEDIF(E45,F45,"M")+1 -> 1 | I45: 50 | J45: =H45*I45 -> 50 | M45: 50 | P45: BT | Q45: Wong Su Fong
...

Sheet Mar-25
A5: 月费善款 收纳表/ Official Receipt Summary: | N5: 2025 年 3 月份 - HLB 05500129613
E6: 赞助的月份
E7: Payment for the month of | K7: 金额 Amount (RM)
A8: 日期 Date | B8: 收据编号 Official Receipt No | C8: 编号 No. | D8: 捐款人 姓名 Name | E8: START MONTH | F8: END MONTH | G8: REF. | K8: 现款 Cash | L8: 支票 Cheque | M8: 网上银行转账 Online Bank Transfer | N8: Bank-in Amount | O8: Bank-in Date | P8: 备注 Remark
A10: 01.03.2025 | B10: CHE 0001118 | C10: 186 | D10: 刘玉云 | E10: 45717 | F10: 45748 | G10: Mar-Apr-25 | H10: =DATEDIF(E10,F10,"M")+1 -> 2 | I10: 50 | J10: =H10*I10 -> 100 | K10: 100 | P10: Book No.23/123 | W10: 45536
A11: 02.03.2025 | B11: CHE 0001119 | C11: 114 | D11: 刁修淋 | E11: 45717 | F11: 45748 | G11: Mar-Apr-25 | H11: =DATEDIF(E11,F11,"M")+1 -> 2 | I11: 50 | J11: =H11*I11 -> 100 | K11: 100 | W11: 45566
A12: 03.03.2025 | B12: CHE 0001120 | C12: 181 | D12: 陈金清 | E12: 45717 | F12: 45748 | G12: Mar-Apr-25 | H12: =DATEDIF(E12,F12,"M")+1 -> 2 | I12: 50 | J12: =H12*I12 -> 100 | K12: 100 | W12: 45597
A13: 03.03.2025 | B13: CHE 0001121 | C13: 170 | D13: 陈柔霓 | E13: 45717 | F13: 45748 | G13: Mar-Apr-25 | H13: =DATEDIF(E13,F13,"M")+1 -> 2 | I13: 50 | J13: =H13*I13 -> 100 | K13: 100 | W13: 45627
A14: 03.03.2025 | B14: CHE 0001122 | C14: 177 | D14: 陈桂香 | E14: 45748 | F14: 45809 | G14: Apr-Jun-25 | H14: =DATEDIF(E14,F14,"M")+1 -> 3 | I14: 50 | J14: =H14*I14 -> 150 | K14: 150 | N14: =SUM(K10:K14) -> 550 | O14: 14.03.2025 | W14: 45658
A15: 10.3.2025 | B15: CHE 0001123 | C15: 208 | D15: 萧志伦 | E15: 45717 | F15: 45717 | G15: 45717 | H15: =DATEDIF(E15,F15,"M")+1 -> 1 | I15: 50 | J15: =H15*I15 -> 50 | K15: 50 | W15: 45689
A16: 14.03.2025 | B16: CHE 0001124 | C16: 227 | D16: 丘桂盈 | E16: 45839 | F16: 45992 | G16: July-Dec-25 | H16: =DATEDIF(E16,F16,"M")+1 -> 6 | I16: 50 | J16: =H16*I16 -> 300 | K16: 300 | W16: 45717
A17: 14.03.2025 | B17: CHE 0001125 | C17: 99 | D17: 吴毓遴 | E17: 45717 | F17: 45748 | G17: Mar-Apr-25 | H17: =DATEDIF(E17,F17,"M")+1 -> 2 | I17: 50 | J17: =H17*I17 -> 100 | K17: 100 | W17: 45748
A18: 18.03.2025 | B18: CHE 0001126 | C18: 136 | D18: 赖宝珍 | E18: 45658 | F18: 45809 | G18: Jan-June-25 | H18: =DATEDIF(E18,F18,"M")+1 -> 6 | I18: 50 | J18: =H18*I18 -> 300 | K18: 300 | W18: 45778
A19: 18.03.2025 | B19: CHE 0001127 | C19: 180 | D19: 蔡健铭 | E19: 45658 | F19: 45717 | G19: Jan-Mar-25 | H19: =DATEDIF(E19,F19,"M")+1 -> 3 | I19: 50 | J19: =H19*I19 -> 150 | K19: 150 | W19: 45809
A20: 18.03.2025 | B20: CHE 0001128 | C20: 72 | D20: 何月琼 | E20: 45658 | F20: 45717 | G20: Jan-Mar-25 | H20: =DATEDIF(E20,F20,"M")+1 -> 3 | I20: 50 | J20: =H20*I20 -> 150 | K20: 150 | W20: 45839
A21: 18.03.2025 | B21: CHE 0001129 | C21: 86 | D21: 蔡祥贤 | E21: 45658 | F21: 45717 | G21: Jan-Mar-25 | H21: =DATEDIF(E21,F21,"M")+1 -> 3 | I21: 50 | J21: =H21*I21 -> 150 | K21: 150 | W21: 45870
A22: 18.03.2025 | B22: CHE 0001130 | C22: 214 | D22: 苏素禛 | E22: 45748 | F22: 45809 | G22: Apr-Jun-25 | H22: =DATEDIF(E22,F22,"M")+1 -> 3 | I22: 50 | J22: =H22*I22 -> 150 | K22: 150 | W22: 45901
A23: 18.03.2025 | B23: CHE 0001131 | C23: 184 | D23: 赖奕坊 | E23: 45717 | F23: 45717 | G23: 45717 | H23: =DATEDIF(E23,F23,"M")+1 -> 1 | I23: 50 | J23: =H23*I23 -> 50 | K23: 50 | W23: 45931
A24: 22.03.2025 | B24: CHE 0001132 | C24: 134 | D24: 黄丽萍 | E24: 45658 | F24: 45809 | G24: Jan-Jun-25 | H24: =DATEDIF(E24,F24,"M")+1 -> 6 | I24: 50 | J24: =H24*I24 -> 300 | K24: 300 | W24: 45962
A25: 22.03.2025 | B25: CHE 0001133 | C25: 135 | D25: 刘永耀 | E25: 45658 | F25: 45809 | G25: Jan-Jun-25 | H25: =DATEDIF(E25,F25,"M")+1 -> 6 | I25: 50 | J25: =H25*I25 -> 300 | K25: 300 | W25: 45992
A26: 29.03.2025 | B26: CHE 0001134 | C26: 164 | D26: 梁佩仪 | E26: 45778 | F26: 45992 | G26: May-Dec-25 | H26: =DATEDIF(E26,F26,"M")+1 -> 8 | I26: 50 | J26: =H26*I26 -> 400 | K26: 400 | N26: =SUM(K15:K26) -> 2400 | O26: 08.04.2025 | W26: 46023
W27: 46054
W28: 46082
W29: 46113
W30: 46143
W31: 46174
W32: 46204
W33: 46235
W34: 46266
A35: 01.03.2025 | B35: CHE0001231 | C35: 14 | D35: 廖佳韵 | E35: 45597 | F35: 45748 | G35: Nov-24-Apr-25 | H35: =DATEDIF(E35,F35,"M")+1 -> 6 | I35: 50 | J35: =H35*I35 -> 300 | M35: 300 | O35: Book No.125 | P35: BT | Q35: Lian Jia Yin | W35: 46296
A36: 02.03.2025 | B36: CHE0001232 | C36: 116 | D36: 李薇薇 | E36: 45717 | F36: 45717 | G36: 45717 | H36: =DATEDIF(E36,F36,"M")+1 -> 1 | I36: 50 | J36: =H36*I36 -> 50 | M36: 50 | P36: BT | Q36: Lee Wei Wei | W36: 46327
A37: 02.03.2025 | B37: CHE0001233 | C37: 117 | D37: 张志文 | E37: 45717 | F37: 45717 | G37: 45717 | H37: =DATEDIF(E37,F37,"M")+1 -> 1 | I37: 50 | J37: =H37*I37 -> 50 | M37: 50 | P37: BT | Q37: Chong Chee Wen | W37: 46357
A38: 02.03.2025 | B38: CHE0001234 | C38: 162 | D38: 方惠贤 | E38: 45717 | F38: 45748 | G38: Mar-Apr-25 | H38: =DATEDIF(E38,F38,"M")+1 -> 2 | I38: 50 | J38: =H38*I38 -> 100 | M38: 100 | P38: BT | Q38: Fong Fui Ying | W38: 46388
A39: 03.03.2025 | B39: CHE0001235 | C39: 123 | D39: 黄丽娟 | E39: 45717 | F39: 45748 | G39: Mar-Apr-25 | H39: =DATEDIF(E39,F39,"M")+1 -> 2 | I39: 50 | J39: =H39*I39 -> 100 | M39: 100 | P39: BT | Q39: Wong Lee Ken
A40: 05.03.2025 | B40: CHE0001236 | C40: 40 | D40: Hoo Mei Sing | E40: 45870 | F40: 45931 | G40: Aug-Oct25 | H40: =DATEDIF(E40,F40,"M")+1 -> 3 | I40: 50 | J40: =H40*I40 -> 150 | M40: 150 | P40: BT | Q40: Hoo Mei Sing
A41: 07.03.2025 | B41: CHE0001237 | C41: 104 | D41: 连美丽 | E41: 45717 | F41: 45748 | G41: Mar-Apr-25 | H41: =DATEDIF(E41,F41,"M")+1 -> 2 | I41: 50 | J41: =H41*I41 -> 100 | M41: 100 | P41: BT | Q41: Lien Mei Li
A42: 09.3.2025 | B42: CHE0001238 | C42: 137 | D42: 赖美珍 | E42: 45717 | F42: 45717 | G42: 45717 | H42: =DATEDIF(E42,F42,"M")+1 -> 1 | I42: 50 | J42: =H42*I42 -> 50 | M42: 50 | P42: CDM
A43: 09.03.2025 | B43: CHE0001239 | C43: 155 | D43: 李宝珠 | E43: 45717 | F43: 45748 | G43: Mar-Apr-25 | H43: =DATEDIF(E43,F43,"M")+1 -> 2 | I43: 50 | J43: =H43*I43 -> 100 | M43: 100 | P43: BT | Q43: Wee Mun Kuan
A44: 09.03.2025 | B44: CHE0001240 | C44: 87 | D44: 叶碧燕 | E44: 45658 | F44: 45992 | G44: Jan-Dec25 | H44: =DATEDIF(E44,F44,"M")+1 -> 12 | I44: 50 | J44: =H44*I44 -> 600 | M44: 600 | P44: BT | Q44: Yap Pik Yin
A45: 13.03.2025 | B45: CHE0001241 | C45: 139 | D45: 黄宝芝 | E45: 45658 | F45: 45992 | G45: Jan-Dec25 | H45: =DATEDIF(E45,F45,"M")+1 -> 12 | I45: 50 | J45: =H45*I45 -> 600 | M45: 600 | P45: BT | Q45: Shereen Wong Poh Chee
...

Sheet Apr-25
AI4: 2025 年 4 月份 - HLB 05500129613
A5: 月费善款 收纳表/ Official Receipt Summary: | E5: 赞助的月份
E6: Payment for the month of | AE6: 金额 Amount (RM) | AI6: ** CDM : Cash Deposit Machine
A7: 日期 Date | B7: 收据编号 Official Receipt No | C7: 月费号码 | D7: 捐款人 姓名 Name | E7: START MONTH | F7: END MONTH | G7: REF. | H7: No.of Month | I7: 月费 | K7: 45566 | L7: 45597 | M7: 45627 | N7: JAN | O7: FEB | P7: MAR | Q7: APR | R7: MAY | S7: JUN | T7: JUL | U7: AUG | V7: SEP | W7: OCT | X7: NOV | Y7: DEC | Z7: 45658 | AA7: 45689 | AB7: 45717 | AC7: No.of Month | AD7: 月费 | AE7: 现款 Cash | AF7: 支票 Cheque | AG7: 网上银行转账 Online Bank Transfer | AH7: CDM SEQ | AI7: (CDM) Bank-in Amount | AJ7: (CDM) Bank-in Date | AK7: 备注 Remark
AE8: RM | AF8: RM
A9: 45748 | B9: CHE 0001135 | C9: 137 | D9: =VLOOKUP(C9,'MASTER Name List'!$B$3:$M$186,2,FALSE) -> 赖美珍 | E9: 45748 | F9: 45748 | G9: 45748 | H9: =DATEDIF(E9,F9,"M")+1 -> 1 | I9: 50 | J9: =H9*I9 -> 50 | Q9: X | AC9: =COUNTIF($K9:$AB9,"X") & "" -> 1 | AD9: 50 | AE9: =COUNTIF($K9:$AB9,"X")*$AD9 -> 50 | AH9: 1 | AK9: 123
A10: 45749 | B10: CHE 0001136 | C10: 4 | D10: =VLOOKUP(C10,'MASTER Name List'!$B$3:$M$186,2,FALSE) -> 邹运金 | E10: 45717 | F10: 45748 | G10: Mar-Apr-25 | H10: =DATEDIF(E10,F10,"M")+1 -> 2 | I10: 50 | J10: =H10*I10 -> 100 | P10: X | Q10: X | AC10: =COUNTIF($K10:$AB10,"X") & "" -> 2 | AD10: 50 | AE10: =COUNTIF($K10:$AB10,"X")*$AD10 -> 100 | AH10: 1
A11: 45755 | B11: CHE 0001137 | C11: 132 | D11: =VLOOKUP(C11,'MASTER Name List'!$B$3:$M$186,2,FALSE) -> 陈杍䍿 | E11: 45778 | F11: 45778 | G11: 45778 | H11: =DATEDIF(E11,F11,"M")+1 -> 1 | I11: 50 | J11: =H11*I11 -> 50 | R11: X | AC11: =COUNTIF($K11:$AB11,"X") & "" -> 1 | AD11: 50 | AE11: =COUNTIF($K11:$AB11,"X")*$AD11 -> 50 | AH11: 1 | AP11: 45536
A12: 45759 | B12: CHE 0001138 | C12: 69 | D12: =VLOOKUP(C12,'MASTER Name List'!$B$3:$M$186,2,FALSE) -> 卢锭伟 | E12: 45839 | F12: 45992 | G12: Jul-Dec-25 | H12: =DATEDIF(E12,F12,"M")+1 -> 6 | I12: 50 | J12: =H12*I12 -> 300 | T12: X | U12: X | V12: X | W12: X | X12: X | Y12: X | AC12: =COUNTIF($K12:$AB12,"X") & "" -> 6 | AD12: 50 | AE12: =COUNTIF($K12:$AB12,"X")*$AD12 -> 300 | AH12: 1 | AI12: =SUMIF(AH:AH,"1",AE:AE) -> 500 | AJ12: 21.04.2025 | AP12: 45566
A13: 45763 | B13: CHE 0001139 | C13: 43 | D13: =VLOOKUP(C13,'MASTER Name List'!$B$3:$M$186,2,FALSE) -> 林德成 | E13: 45748 | F13: 45809 | G13: Apr-Jun'25 | H13: =DATEDIF(E13,F13,"M")+1 -> 3 | I13: 50 | J13: =H13*I13 -> 150 | Q13: X | R13: X | S13: X | AC13: =COUNTIF($K13:$AB13,"X") & "" -> 3 | AD13: 50 | AE13: =COUNTIF($K13:$AB13,"X")*$AD13 -> 150 | AH13: 2 | AP13: 45597
A14: 45769 | B14: CHE 0001140 | C14: 185 | D14: =VLOOKUP(C14,'MASTER Name List'!$B$3:$M$186,2,FALSE) -> 羅梅瑂 | E14: 45717 | F14: 45809 | G14: Mar-Jun'25 | H14: =DATEDIF(E14,F14,"M")+1 -> 4 | I14: 50 | J14: =H14*I14 -> 200 | P14: X | Q14: X | R14: X | S14: X | AC14: =COUNTIF($K14:$AB14,"X") & "" -> 4 | AD14: 50 | AE14: =COUNTIF($K14:$AB14,"X")*$AD14 -> 200 | AH14: 2 | AP14: 45627
A15: 45770 | B15: CHE 0001141 | C15: 126 | D15: =VLOOKUP(C15,'MASTER Name List'!$B$3:$M$186,2,FALSE) -> 张凤 | E15: 45748 | F15: 45809 | G15: Apr-Jun'25 | H15: =DATEDIF(E15,F15,"M")+1 -> 3 | I15: 50 | J15: =H15*I15 -> 150 | Q15: X | R15: X | S15: X | AC15: =COUNTIF($K15:$AB15,"X") & "" -> 3 | AD15: 50 | AE15: =COUNTIF($K15:$AB15,"X")*$AD15 -> 150 | AH15: 2 | AP15: 45658
A16: 45772 | B16: CHE 0001142 | C16: 168 | D16: =VLOOKUP(C16,'MASTER Name List'!$B$3:$M$186,2,FALSE) -> 王秋蓉 | E16: 45717 | F16: 45748 | G16: Mar-Apr-25 | H16: =DATEDIF(E16,F16,"M")+1 -> 2 | I16: 50 | J16: =H16*I16 -> 100 | P16: X | Q16: X | AC16: =COUNTIF($K16:$AB16,"X") & "" -> 2 | AD16: 50 | AE16: =COUNTIF($K16:$AB16,"X")*$AD16 -> 100 | AH16: 2 | AI16: =SUMIF(AH:AH,"2",AE:AE) -> 600 | AJ16: 28.04.2025 | AP16: 45689
A17: 45775 | B17: CHE 0001143 | C17: 178 | D17: =VLOOKUP(C17,'MASTER Name List'!$B$3:$M$186,2,FALSE) -> 颜美葒 | E17: 45748 | F17: 45809 | G17: Apr-Jun'25 | H17: =DATEDIF(E17,F17,"M")+1 -> 3 | I17: 50 | J17: =H17*I17 -> 150 | Q17: X | R17: X | S17: X | AC17: =COUNTIF($K17:$AB17,"X") & "" -> 3 | AD17: 50 | AE17: =COUNTIF($K17:$AB17,"X")*$AD17 -> 150 | AH17: 3 | AP17: 45717
A18: 45775 | B18: CHE 0001144 | C18: 131 | D18: =VLOOKUP(C18,'MASTER Name List'!$B$3:$M$186,2,FALSE) -> 王康芬 | E18: 45748 | F18: 45778 | G18: Apr-May'25 | H18: =DATEDIF(E18,F18,"M")+1 -> 2 | I18: 50 | J18: =H18*I18 -> 100 | Q18: X | R18: X | AC18: =COUNTIF($K18:$AB18,"X") & "" -> 2 | AD18: 50 | AE18: =COUNTIF($K18:$AB18,"X")*$AD18 -> 100 | AH18: 3 | AI18: =SUMIF(AH:AH,"3",AE:AE) -> 250 | AJ18: 19.05.2025 | AP18: 45748
D19: =VLOOKUP(C19,'MASTER Name List'!$B$3:$M$186,2,FALSE) -> #N/A | H19: =DATEDIF(E19,F19,"M")+1 -> 1 | I19: 50 | J19: =H19*I19 -> 50 | AC19: =COUNTIF($K19:$AB19,"X") & "" -> 0 | AD19: 50 | AE19: =COUNTIF($K19:$AB19,"X")*$AD19 -> 0 | AP19: 45778
D20: =VLOOKUP(C20,'MASTER Name List'!$B$3:$M$186,2,FALSE) -> #N/A | H20: =DATEDIF(E20,F20,"M")+1 -> 1 | I20: 50 | J20: =H20*I20 -> 50 | AC20: =COUNTIF($K20:$AB20,"X") & "" -> 0 | AD20: 50 | AE20: =COUNTIF($K20:$AB20,"X")*$AD20 -> 0 | AP20: 45809
D21: =VLOOKUP(C21,'MASTER Name List'!$B$3:$M$186,2,FALSE) -> #N/A | H21: =DATEDIF(E21,F21,"M")+1 -> 1 | I21: 50 | J21: =H21*I21 -> 50 | AC21: =COUNTIF($K21:$AB21,"X") & "" -> 0 | AD21: 50 | AE21: =COUNTIF($K21:$AB21,"X")*$AD21 -> 0 | AP21: 45839
D22: =VLOOKUP(C22,'MASTER Name List'!$B$3:$M$186,2,FALSE) -> #N/A | H22: =DATEDIF(E22,F22,"M")+1 -> 1 | I22: 50 | J22: =H22*I22 -> 50 | AP22: 45870
D23: =VLOOKUP(C23,'MASTER Name List'!$B$3:$M$186,2,FALSE) -> #N/A | H23: =DATEDIF(E23,F23,"M")+1 -> 1 | I23: 50 | J23: =H23*I23 -> 50 | AP23: 45901
H24: =DATEDIF(E24,F24,"M")+1 -> 1 | I24: 50 | J24: =H24*I24 -> 50 | AP24: 45931
B25: BANK IN | H25: =DATEDIF(E25,F25,"M")+1 -> 1 | I25: 50 | J25: =H25*I25 -> 50 | AP25: 45962
A26: 45748 | B26: CHE0001250 | C26: 116 | D26: =VLOOKUP(C26,'MASTER Name List'!$B$3:$M$186,2,FALSE) -> 李薇薇 | E26: 45748 | F26: 45748 | G26: Apr'25 | H26: =DATEDIF(E26,F26,"M")+1 -> 1 | I26: 50 | J26: =H26*I26 -> 50 | Q26: X | AC26: =COUNTIF($K26:$AB26,"X") & "" -> 1 | AD26: 50 | AG26: =COUNTIF($K26:$AB26,"X")*$AD26 -> 50 | AJ26: Book No.125 | AK26: BT | AL26: Lee Wei Wei | AP26: 45992
A27: 45749 | B27: CHE0001301 | C27: 117 | D27: =VLOOKUP(C27,'MASTER Name List'!$B$3:$M$186,2,FALSE) -> 张志文 | E27: 45748 | F27: 45748 | G27: Apr'25 | H27: =DATEDIF(E27,F27,"M")+1 -> 1 | I27: 50 | J27: =H27*I27 -> 50 | Q27: X | AC27: =COUNTIF($K27:$AB27,"X") & "" -> 1 | AD27: 50 | AG27: =COUNTIF($K27:$AB27,"X")*$AD27 -> 50 | AJ27: Book No.127 | AK27: BT | AL27: Lee Wei Wei / Chong Chee Wen | AP27: 46023
A28: 45749 | B28: CHE0001302 | C28: 173 | D28: =VLOOKUP(C28,'MASTER Name List'!$B$3:$M$186,2,FALSE) -> 张杍䌻 | E28: 45689 | F28: 45839 | G28: Feb - Jul'25 | H28: =DATEDIF(E28,F28,"M")+1 -> 6 | I28: 50 | J28: =H28*I28 -> 300 | O28: X | P28: X | Q28: X | R28: X | S28: X | T28: X | AC28: =COUNTIF($K28:$AB28,"X") & "" -> 6 | AD28: 50 | AG28: =COUNTIF($K28:$AB28,"X")*$AD28 -> 300 | AK28: BT | AL28: Florence Chong / Chong Nyok Moi | AP28: 46054
A29: 45753 | B29: CHE0001303 | C29: 162 | D29: =VLOOKUP(C29,'MASTER Name List'!$B$3:$M$186,2,FALSE) -> 方惠贤 | E29: 45778 | F29: 45809 | G29: May, Jun'25 | H29: =DATEDIF(E29,F29,"M")+1 -> 2 | I29: 50 | J29: =H29*I29 -> 100 | R29: X | S29: X | AC29: =COUNTIF($K29:$AB29,"X") & "" -> 2 | AD29: 50 | AG29: =COUNTIF($K29:$AB29,"X")*$AD29 -> 100 | AK29: BT | AL29: Fong Fui Ying | AP29: 46082
A30: 45754 | B30: CHE0001304 | C30: 172 | D30: =VLOOKUP(C30,'MASTER Name List'!$B$3:$M$186,2,FALSE) -> 蔡均镅 | E30: 45717 | F30: 45748 | G30: Mar, Apr'25 | H30: =DATEDIF(E30,F30,"M")+1 -> 2 | I30: 50 | J30: =H30*I30 -> 100 | P30: X | Q30: X | AC30: =COUNTIF($K30:$AB30,"X") & "" -> 2 | AD30: 50 | AG30: =COUNTIF($K30:$AB30,"X")*$AD30 -> 100 | AK30: BT | AL30: Chua Jiun Mei | AP30: 46113
A31: 45755 | B31: CHE0001305 | C31: 40 | D31: =VLOOKUP(C31,'MASTER Name List'!$B$3:$M$186,2,FALSE) -> 何梅歆 | E31: 45962 | F31: 45992 | G31: Nov, Dec'25 | H31: =DATEDIF(E31,F31,"M")+1 -> 2 | I31: 50 | J31: =H31*I31 -> 100 | X31: X | Y31: X | AC31: =COUNTIF($K31:$AB31,"X") & "" -> 2 | AD31: 50 | AG31: =COUNTIF($K31:$AB31,"X")*$AD31 -> 100 | AK31: BT | AL31: Hoo Mei Sing | AP31: 46143
A32: 45759 | B32: CHE0001306 | C32: 175 | D32: =VLOOKUP(C32,'MASTER Name List'!$B$3:$M$186,2,FALSE) -> 洪鼎惟 | E32: 45748 | F32: 45748 | G32: Apr'25 | H32: =DATEDIF(E32,F32,"M")+1 -> 1 | I32: 50 | J32: =H32*I32 -> 50 | Q32: X | AC32: =COUNTIF($K32:$AB32,"X") & "" -> 1 | AD32: 50 | AG32: =COUNTIF($K32:$AB32,"X")*$AD32 -> 50 | AK32: BT | AL32: Hoon Teng Hui | AP32: 46174
A33: 45760 | B33: CHE0001307 | C33: 130 | D33: =VLOOKUP(C33,'MASTER Name List'!$B$3:$M$186,2,FALSE) -> 王丽珠 | E33: 45597 | F33: 45778 | G33: Nov'24-May'25 | H33: =DATEDIF(E33,F33,"M")+1 -> 7 | I33: 50 | J33: =H33*I33 -> 350 | L33: X | M33: X | N33: X | O33: X | P33: X | Q33: X | R33: X | AC33: =COUNTIF($K33:$AB33,"X") & "" -> 7 | AD33: 50 | AG33: =COUNTIF($K33:$AB33,"X")*$AD33 -> 350 | AK33: BT | AL33: Wong Lay Choo | AP33: 46204
A34: 45761 | B34: CHE0001308 | C34: 52 | D34: =VLOOKUP(C34,'MASTER Name List'!$B$3:$M$186,2,FALSE) -> 陈宝蓉 | E34: 45717 | F34: 45748 | G34: Mar_Apr25 | H34: =DATEDIF(E34,F34,"M")+1 -> 2 | I34: 50 | J34: =H34*I34 -> 100 | P34: X | Q34: X | AC34: =COUNTIF($K34:$AB34,"X") & "" -> 2 | AD34: 50 | AG34: =COUNTIF($K34:$AB34,"X")*$AD34 -> 100 | AK34: BT | AL34: Tan Poh Yong | AP34: 46235
A35: 45769 | B35: CHE0001309 | C35: 94 | D35: =VLOOKUP(C35,'MASTER Name List'!$B$3:$M$186,2,FALSE) -> 余合福 | E35: 45839 | F35: 46174 | G35: Jul25_Jun26 | H35: =DATEDIF(E35,F35,"M")+1 -> 12 | I35: 50 | J35: =H35*I35 -> 600 | T35: X | U35: X | V35: X | W35: X | X35: X | Y35: X | Z35: X | AA35: X | AB35: X | AC35: =COUNTIF($K35:$AB35,"X") & "" -> 9 | AD35: 50 | AG35: =COUNTIF($K35:$AB35,"X")*$AD35 -> 450 | AK35: BT | AL35: Pusat Perkahwinan Inovatif | AP35: 46266
A36: 45777 | B36: CHE0001310 | C36: 80 | D36: =VLOOKUP(C36,'MASTER Name List'!$B$3:$M$186,2,FALSE) -> 黄淑芬 | E36: 45778 | F36: 45778 | G36: 45778 | H36: =DATEDIF(E36,F36,"M")+1 -> 1 | I36: 50 | J36: =H36*I36 -> 50 | R36: X | AC36: =COUNTIF($K36:$AB36,"X") & "" -> 1 | AD36: 50 | AG36: =COUNTIF($K36:$AB36,"X")*$AD36 -> 50 | AK36: BT | AL36: Wong Su Fong | AP36: 46296
A37: 45777 | B37: CHE0001311 | C37: 224 | D37: =VLOOKUP(C37,'MASTER Name List'!$B$3:$M$186,2,FALSE) -> 黄文勝 | E37: 45778 | F37: 45778 | G37: 45778 | H37: =DATEDIF(E37,F37,"M")+1 -> 1 | I37: 50 | J37: =H37*I37 -> 50 | R37: X | AC37: =COUNTIF($K37:$AB37,"X") & "" -> 1 | AD37: 50 | AG37: =COUNTIF($K37:$AB37,"X")*$AD37 -> 50 | AP37: 46327
D38: =VLOOKUP(C38,'MASTER Name List'!$B$3:$M$186,2,FALSE) -> #N/A | H38: =DATEDIF(E38,F38,"M")+1 -> 1 | I38: 50 | J38: =H38*I38 -> 50 | AC38: =COUNTIF($K38:$AB38,"X") & "" -> 0 | AD38: 50 | AG38: =COUNTIF($K38:$AB38,"X")*$AD38 -> 0 | AP38: 46357
D39: =VLOOKUP(C39,'MASTER Name List'!$B$3:$M$186,2,FALSE) -> #N/A | H39: =DATEDIF(E39,F39,"M")+1 -> 1 | I39: 50 | J39: =H39*I39 -> 50 | AC39: =COUNTIF($K39:$AB39,"X") & "" -> 0 | AD39: 50 | AG39: =COUNTIF($K39:$AB39,"X")*$AD39 -> 0 | AP39: 46388
D40: =VLOOKUP(C40,'MASTER Name List'!$B$3:$M$186,2,FALSE) -> #N/A | H40: =DATEDIF(E40,F40,"M")+1 -> 1 | I40: 50 | J40: =H40*I40 -> 50 | AC40: =COUNTIF($K40:$AB40,"X") & "" -> 0 | AD40: 50 | AG40: =COUNTIF($K40:$AB40,"X")*$AD40 -> 0
D41: =VLOOKUP(C41,'MASTER Name List'!$B$3:$M$186,2,FALSE) -> #N/A | H41: =DATEDIF(E41,F41,"M")+1 -> 1 | I41: 50 | J41: =H41*I41 -> 50 | AC41: =COUNTIF($K41:$AB41,"X") & "" -> 0 | AD41: 50 | AG41: =COUNTIF($K41:$AB41,"X")*$AD41 -> 0
D42: =VLOOKUP(C42,'MASTER Name List'!$B$3:$M$186,2,FALSE) -> #N/A | H42: =DATEDIF(E42,F42,"M")+1 -> 1 | I42: 50 | J42: =H42*I42 -> 50 | AC42: =COUNTIF($K42:$AB42,"X") & "" -> 0 | AD42: 50 | AG42: =COUNTIF($K42:$AB42,"X")*$AD42 -> 0
D43: =VLOOKUP(C43,'MASTER Name List'!$B$3:$M$186,2,FALSE) -> #N/A | H43: =DATEDIF(E43,F43,"M")+1 -> 1 | I43: 50 | J43: =H43*I43 -> 50 | AC43: =COUNTIF($K43:$AB43,"X") & "" -> 0 | AD43: 50 | AG43: =COUNTIF($K43:$AB43,"X")*$AD43 -> 0
...

Sheet May-25
AD4: 2025 年 5 月份 - HLB 05500129613
A5: 月费善款 收纳表/ Official Receipt Summary:
F6: 10 | G6: 11 | H6: 12 | I6: 1 | J6: 2 | K6: 3 | L6: 4 | M6: 5 | N6: 6 | O6: 7 | P6: 8 | Q6: 9 | R6: 10 | S6: 11 | T6: 12 | U6: 1 | V6: 2 | W6: 3 | Z6: 金额 Amount (RM) | AD6: ** CDM : Cash Deposit Machine
A7: 日期 Date | B7: 收据编号 Official Receipt No | C7: 月费号码 | D7: 捐款人 姓名 Name | E7: 赞助的月份 Payment for the month of | F7: 45566 | G7: 45597 | H7: 45627 | I7: JAN | J7: FEB | K7: MAR | L7: APR | M7: MAY | N7: JUN | O7: JUL | P7: AUG | Q7: SEP | R7: OCT | S7: NOV | T7: DEC | U7: 45658 | V7: 45689 | W7: 45717 | X7: No.of Month | Y7: 月费 | Z7: 现款 Cash | AA7: 支票 Cheque | AB7: 网上银行转账 Online Bank Transfer | AC7: CDM SEQ | AD7: (CDM) Bank-in Amount | AE7: (CDM) Bank-in Date | AF7: 备注 Remark
Z8: RM | AA8: RM
A9: 45782 | B9: CHE 0001145 | C9: 168 | D9: =VLOOKUP(C9,'MASTER Name List'!$B$3:$M$186,2,FALSE) -> 王秋蓉 | E9: May-Jun'25 | M9: X | N9: X | X9: =COUNTIF($F9:$W9,"X") & "" -> 2 | Y9: 50 | Z9: =COUNTIF($F9:$W9,"X")*$Y9 -> 100 | AC9: 1 | AF9: 123
A10: 45787 | B10: CHE 0001146 | C10: 186 | D10: =VLOOKUP(C10,'MASTER Name List'!$B$3:$M$186,2,FALSE) -> 刘玉云 | E10: May-Jun'25 | M10: X | N10: X | X10: =COUNTIF($F10:$W10,"X") & "" -> 2 | Y10: 50 | Z10: =COUNTIF($F10:$W10,"X")*$Y10 -> 100 | AC10: 1
A11: 45789 | B11: CHE 0001147 | C11: 73 | D11: =VLOOKUP(C11,'MASTER Name List'!$B$3:$M$186,2,FALSE) -> 李宝明 | E11: May-Aug'25 | M11: X | N11: X | O11: X | P11: X | X11: =COUNTIF($F11:$W11,"X") & "" -> 4 | Y11: 50 | Z11: =COUNTIF($F11:$W11,"X")*$Y11 -> 200 | AC11: 1
A12: 45789 | B12: CHE 0001148 | C12: 208 | D12: =VLOOKUP(C12,'MASTER Name List'!$B$3:$M$186,2,FALSE) -> 萧志倫 | E12: Apr-May'25 | L12: X | M12: X | X12: =COUNTIF($F12:$W12,"X") & "" -> 2 | Y12: 50 | Z12: =COUNTIF($F12:$W12,"X")*$Y12 -> 100 | AC12: 1
A13: 45789 | B13: CHE 0001149 | C13: 178 | D13: =VLOOKUP(C13,'MASTER Name List'!$B$3:$M$186,2,FALSE) -> 颜美葒 | E13: Jul'25 | O13: X | X13: =COUNTIF($F13:$W13,"X") & "" -> 1 | Y13: 50 | Z13: =COUNTIF($F13:$W13,"X")*$Y13 -> 50 | AC13: 1
A14: 45789 | B14: CHE 0001150 | C14: 97 | D14: =VLOOKUP(C14,'MASTER Name List'!$B$3:$M$186,2,FALSE) -> 陈素秋 | E14: May-Aug'25 | M14: X | N14: X | O14: X | P14: X | X14: =COUNTIF($F14:$W14,"X") & "" -> 4 | Y14: 50 | Z14: =COUNTIF($F14:$W14,"X")*$Y14 -> 200 | AC14: 1 | AD14: =SUMIF(AC:AC,"1",Z:Z) -> 750 | AE14: 19.05.2025 | AF14: 123
A15: 45792 | B15: CHE 0001151 | C15: 229 | D15: =VLOOKUP(C15,'MASTER Name List'!$B$3:$M$186,2,FALSE) -> 陈丽珍 | E15: May-Aug'25 | M15: X | N15: X | O15: X | P15: X | X15: =COUNTIF($F15:$W15,"X") & "" -> 4 | Y15: 50 | Z15: =COUNTIF($F15:$W15,"X")*$Y15 -> 200 | AC15: 2 | AF15: 124
A16: 45793 | B16: CHE 0001152 | C16: 183 | D16: =VLOOKUP(C16,'MASTER Name List'!$B$3:$M$186,2,FALSE) -> 郭丽诗 | E16: Jun-Dec'25 | N16: X | O16: X | P16: X | Q16: X | R16: X | S16: X | T16: X | X16: =COUNTIF($F16:$W16,"X") & "" -> 7 | Y16: 50 | Z16: =COUNTIF($F16:$W16,"X")*$Y16 -> 350 | AC16: 2 | AD16: =SUMIF(AC:AC,"2",Z:Z) -> 550 | AE16: 19.05.2025
A17: 45799 | B17: CHE 0001153 | C17: 181 | D17: =VLOOKUP(C17,'MASTER Name List'!$B$3:$M$186,2,FALSE) -> 陈金清 | E17: May-Jun'25 | M17: X | N17: X | X17: =COUNTIF($F17:$W17,"X") & "" -> 2 | Y17: 50 | Z17: =COUNTIF($F17:$W17,"X")*$Y17 -> 100 | AC17: 3
A18: 45801 | B18: CHE 0001154 | C18: 184 | D18: =VLOOKUP(C18,'MASTER Name List'!$B$3:$M$186,2,FALSE) -> 赖奕坊 | E18: Apr-Jul'25 | L18: X | M18: X | N18: X | O18: X | X18: =COUNTIF($F18:$W18,"X") & "" -> 4 | Y18: 50 | Z18: =COUNTIF($F18:$W18,"X")*$Y18 -> 200 | AC18: 3
A19: 45804 | B19: CHE 0001155 | C19: 74 | D19: =VLOOKUP(C19,'MASTER Name List'!$B$3:$M$186,2,FALSE) -> 黄得财 | E19: Jun-Dec'25 | N19: X | O19: X | P19: X | Q19: X | R19: X | S19: X | T19: X | X19: =COUNTIF($F19:$W19,"X") & "" -> 7 | Y19: 50 | Z19: =COUNTIF($F19:$W19,"X")*$Y19 -> 350 | AC19: 3
A20: 45804 | B20: CHE 0001156 | C20: 103 | D20: =VLOOKUP(C20,'MASTER Name List'!$B$3:$M$186,2,FALSE) -> 林采諺 | E20: May-Aug'25 | M20: X | N20: X | O20: X | P20: X | X20: =COUNTIF($F20:$W20,"X") & "" -> 4 | Y20: 50 | Z20: =COUNTIF($F20:$W20,"X")*$Y20 -> 200 | AC20: 3
A21: 45804 | B21: CHE 0001157 | C21: 131 | D21: =VLOOKUP(C21,'MASTER Name List'!$B$3:$M$186,2,FALSE) -> 王康芬 | E21: Jun-Aug'25 | N21: X | O21: X | P21: X | X21: =COUNTIF($F21:$W21,"X") & "" -> 3 | Y21: 50 | Z21: =COUNTIF($F21:$W21,"X")*$Y21 -> 150 | AC21: 3 | AD21: =SUMIF(AC:AC,"3",Z:Z) -> 1000 | AE21: 04.06.2025
D22: =VLOOKUP(C22,'MASTER Name List'!$B$3:$M$186,2,FALSE) -> #N/A
D23: =VLOOKUP(C23,'MASTER Name List'!$B$3:$M$186,2,FALSE) -> #N/A
B25: BANK IN
A26: 45778 | C26: 145 | D26: =VLOOKUP(C26,'MASTER Name List'!$B$3:$M$186,2,FALSE) -> 许俊豪 | E26: May-Aug25 | M26: X | N26: X | O26: X | P26: X | X26: =COUNTIF($F26:$W26,"X") & "" -> 4 | Y26: 50 | AB26: =COUNTIF($F26:$W26,"X")*$Y26 -> 200 | AF26: BT | AG26: Khor Chun Hoe | AJ26: #145
A27: 45779 | C27: 116 | D27: =VLOOKUP(C27,'MASTER Name List'!$B$3:$M$186,2,FALSE) -> 李薇薇 | E27: 45778 | M27: X | X27: =COUNTIF($F27:$W27,"X") & "" -> 1 | Y27: 50 | AB27: =COUNTIF($F27:$W27,"X")*$Y27 -> 50 | AF27: BT | AG27: Lee Wei Wei | AJ27: #116
A28: 45779 | C28: 117 | D28: =VLOOKUP(C28,'MASTER Name List'!$B$3:$M$186,2,FALSE) -> 张志文 | E28: 45778 | M28: X | X28: =COUNTIF($F28:$W28,"X") & "" -> 1 | Y28: 50 | AB28: =COUNTIF($F28:$W28,"X")*$Y28 -> 50 | AF28: BT | AG28: Lee Wei Wei / Chong Chee Wen | AJ28: #117
A29: 45779 | C29: 123 | D29: =VLOOKUP(C29,'MASTER Name List'!$B$3:$M$186,2,FALSE) -> 黄丽娟 | E29: May_Jun25 | M29: X | N29: X | X29: =COUNTIF($F29:$W29,"X") & "" -> 2 | Y29: 50 | AB29: =COUNTIF($F29:$W29,"X")*$Y29 -> 100 | AF29: BT | AG29: Wong Lee Ken | AI29: #123
A30: 45781 | C30: 137 | D30: =VLOOKUP(C30,'MASTER Name List'!$B$3:$M$186,2,FALSE) -> 赖美珍 | E30: 45778 | M30: X | X30: =COUNTIF($F30:$W30,"X") & "" -> 1 | Y30: 50 | AB30: =COUNTIF($F30:$W30,"X")*$Y30 -> 50 | AF30: ATM | AI30: #137
A31: 45781 | C31: 68 | D31: =VLOOKUP(C31,'MASTER Name List'!$B$3:$M$186,2,FALSE) -> 沈观胜 | E31: Apr_Jun25 | L31: X | M31: X | N31: X | X31: =COUNTIF($F31:$W31,"X") & "" -> 3 | Y31: 50 | AB31: =COUNTIF($F31:$W31,"X")*$Y31 -> 150 | AF31: BT | AG31: Sim Kuan Seng | AI31: #68
A32: 45782 | C32: 104 | D32: =VLOOKUP(C32,'MASTER Name List'!$B$3:$M$186,2,FALSE) -> 连美丽 | E32: May_Jun25 | M32: X | N32: X | X32: =COUNTIF($F32:$W32,"X") & "" -> 2 | Y32: 50 | AB32: =COUNTIF($F32:$W32,"X")*$Y32 -> 100 | AF32: BT | AG32: Lien Mei Li | AI32: #104
A33: 45786 | C33: 172 | D33: =VLOOKUP(C33,'MASTER Name List'!$B$3:$M$186,2,FALSE) -> 蔡均镅 | E33: May_Jun25 | M33: X | N33: X | X33: =COUNTIF($F33:$W33,"X") & "" -> 2 | Y33: 50 | AB33: =COUNTIF($F33:$W33,"X")*$Y33 -> 100 | AF33: BT | AG33: Chua Jiun Mei
A34: 45787 | C34: 24 | D34: =VLOOKUP(C34,'MASTER Name List'!$B$3:$M$186,2,FALSE) -> 陈淑心 | E34: Apr_Jun25 | L34: X | M34: X | N34: X | X34: =COUNTIF($F34:$W34,"X") & "" -> 3 | Y34: 50 | AB34: =COUNTIF($F34:$W34,"X")*$Y34 -> 150 | AF34: BT
A35: 45788 | C35: 155 | D35: =VLOOKUP(C35,'MASTER Name List'!$B$3:$M$186,2,FALSE) -> 李宝珠 | E35: May_Jun25 | M35: X | N35: X | X35: =COUNTIF($F35:$W35,"X") & "" -> 2 | Y35: 50 | AB35: =COUNTIF($F35:$W35,"X")*$Y35 -> 100 | AF35: BT | AG35: Lee Poh Choo
A36: 45789 | C36: 175 | D36: =VLOOKUP(C36,'MASTER Name List'!$B$3:$M$186,2,FALSE) -> 洪鼎惟 | E36: 45778 | M36: X | X36: =COUNTIF($F36:$W36,"X") & "" -> 1 | Y36: 50 | AB36: =COUNTIF($F36:$W36,"X")*$Y36 -> 50 | AF36: BT | AG36: Hoon Teng Hui
A37: 45791 | C37: 40 | D37: =VLOOKUP(C37,'MASTER Name List'!$B$3:$M$186,2,FALSE) -> 何梅歆 | E37: 46023 | U37: X | X37: =COUNTIF($F37:$W37,"X") & "" -> 1 | Y37: 50 | AB37: =COUNTIF($F37:$W37,"X")*$Y37 -> 50 | AG37: Hoo Mei Sing
D38: =VLOOKUP(C38,'MASTER Name List'!$B$3:$M$186,2,FALSE) -> #N/A | X38: =COUNTIF($F38:$W38,"X") & "" -> 0 | Y38: 50 | AB38: =COUNTIF($F38:$W38,"X")*$Y38 -> 0
D39: =VLOOKUP(C39,'MASTER Name List'!$B$3:$M$186,2,FALSE) -> #N/A | X39: =COUNTIF($F39:$W39,"X") & "" -> 0 | Y39: 50 | AB39: =COUNTIF($F39:$W39,"X")*$Y39 -> 0
D40: =VLOOKUP(C40,'MASTER Name List'!$B$3:$M$186,2,FALSE) -> #N/A | X40: =COUNTIF($F40:$W40,"X") & "" -> 0 | Y40: 50 | AB40: =COUNTIF($F40:$W40,"X")*$Y40 -> 0
D41: =VLOOKUP(C41,'MASTER Name List'!$B$3:$M$186,2,FALSE) -> #N/A | X41: =COUNTIF($F41:$W41,"X") & "" -> 0 | Y41: 50 | AB41: =COUNTIF($F41:$W41,"X")*$Y41 -> 0
D42: =VLOOKUP(C42,'MASTER Name List'!$B$3:$M$186,2,FALSE) -> #N/A | X42: =COUNTIF($F42:$W42,"X") & "" -> 0 | Y42: 50 | AB42: =COUNTIF($F42:$W42,"X")*$Y42 -> 0
D43: =VLOOKUP(C43,'MASTER Name List'!$B$3:$M$186,2,FALSE) -> #N/A | X43: =COUNTIF($F43:$W43,"X") & "" -> 0 | Y43: 50 | AB43: =COUNTIF($F43:$W43,"X")*$Y43 -> 0
AB44: =COUNTIF($F44:$W44,"X")*$Y44 -> 0
...

Sheet May-25 (New)
N4: 2025 年 5 月份 - HLB 05500129613
A5: 月费善款 收纳表/ Official Receipt Summary: | E5: 赞助的月份
E6: Payment for the month of | J6: 金额 Amount (RM) | N6: ** CDM : Cash Deposit Machine
A7: 日期 Date | B7: 收据编号 Official Receipt No | C7: 月费号码 | D7: 捐款人 姓名 Name | E7: START MONTH | F7: END MONTH | G7: REF. | H7: No.of Month | I7: 月费 | J7: 现款 Cash | K7: 支票 Cheque | L7: 网上银行转账 Online Bank Transfer | M7: CDM SEQ | N7: (CDM) Bank-in Amount | O7: (CDM) Bank-in Date | P7: 备注 Remark
J8: RM | K8: RM
A9: 45782 | B9: CHE 0001145 | C9: 168 | D9: =VLOOKUP(C9,'MASTER Name List'!$B$3:$M$186,2,FALSE) -> 王秋蓉 | E9: 45778 | F9: 45809 | G9: May-Jun'25 | H9: =DATEDIF(E9,F9,"M")+1 -> 2 | I9: 50 | J9: =$H9*$I9 -> 100 | M9: 1 | P9: 123
A10: 45787 | B10: CHE 0001146 | C10: 186 | D10: =VLOOKUP(C10,'MASTER Name List'!$B$3:$M$186,2,FALSE) -> 刘玉云 | E10: 45778 | F10: 45809 | G10: May-Jun'25 | H10: =DATEDIF(E10,F10,"M")+1 -> 2 | I10: 50 | J10: =$H10*$I10 -> 100 | M10: 1 | U10: 45536
A11: 45789 | B11: CHE 0001147 | C11: 73 | D11: =VLOOKUP(C11,'MASTER Name List'!$B$3:$M$186,2,FALSE) -> 李宝明 | E11: 45778 | F11: 45870 | G11: May-Aug'25 | H11: =DATEDIF(E11,F11,"M")+1 -> 4 | I11: 50 | J11: =$H11*$I11 -> 200 | M11: 1 | U11: 45566
A12: 45789 | B12: CHE 0001148 | C12: 208 | D12: =VLOOKUP(C12,'MASTER Name List'!$B$3:$M$186,2,FALSE) -> 萧志倫 | E12: 45748 | F12: 45778 | G12: Apr-May'25 | H12: =DATEDIF(E12,F12,"M")+1 -> 2 | I12: 50 | J12: =$H12*$I12 -> 100 | M12: 1 | U12: 45597
A13: 45789 | B13: CHE 0001149 | C13: 178 | D13: =VLOOKUP(C13,'MASTER Name List'!$B$3:$M$186,2,FALSE) -> 颜美葒 | E13: 45839 | F13: 45839 | G13: Jul'25 | H13: =DATEDIF(E13,F13,"M")+1 -> 1 | I13: 50 | J13: =$H13*$I13 -> 50 | M13: 1 | U13: 45627
A14: 45789 | B14: CHE 0001150 | C14: 97 | D14: =VLOOKUP(C14,'MASTER Name List'!$B$3:$M$186,2,FALSE) -> 陈素秋 | E14: 45778 | F14: 45870 | G14: May-Aug'25 | H14: =DATEDIF(E14,F14,"M")+1 -> 4 | I14: 50 | J14: =$H14*$I14 -> 200 | M14: 1 | N14: =SUMIF(M:M,"1",J:J) -> 750 | O14: 19.05.2025 | P14: 123 | U14: 45658
A15: 45792 | B15: CHE 0001151 | C15: 229 | D15: =VLOOKUP(C15,'MASTER Name List'!$B$3:$M$186,2,FALSE) -> 陈丽珍 | E15: 45778 | F15: 45870 | G15: May-Aug'25 | H15: =DATEDIF(E15,F15,"M")+1 -> 4 | I15: 50 | J15: =$H15*$I15 -> 200 | M15: 2 | P15: 124 | U15: 45689
A16: 45793 | B16: CHE 0001152 | C16: 183 | D16: =VLOOKUP(C16,'MASTER Name List'!$B$3:$M$186,2,FALSE) -> 郭丽诗 | E16: 45809 | F16: 45992 | G16: Jun-Dec'25 | H16: =DATEDIF(E16,F16,"M")+1 -> 7 | I16: 50 | J16: =$H16*$I16 -> 350 | M16: 2 | N16: =SUMIF(M:M,"2",J:J) -> 550 | O16: 19.05.2025 | U16: 45717
A17: 45799 | B17: CHE 0001153 | C17: 181 | D17: =VLOOKUP(C17,'MASTER Name List'!$B$3:$M$186,2,FALSE) -> 陈金清 | E17: 45778 | F17: 45809 | G17: May-Jun'25 | H17: =DATEDIF(E17,F17,"M")+1 -> 2 | I17: 50 | J17: =$H17*$I17 -> 100 | M17: 3 | U17: 45748
A18: 45801 | B18: CHE 0001154 | C18: 184 | D18: =VLOOKUP(C18,'MASTER Name List'!$B$3:$M$186,2,FALSE) -> 赖奕坊 | E18: 45748 | F18: 45839 | G18: Apr-Jul'25 | H18: =DATEDIF(E18,F18,"M")+1 -> 4 | I18: 50 | J18: =$H18*$I18 -> 200 | M18: 3 | U18: 45778
A19: 45804 | B19: CHE 0001155 | C19: 74 | D19: =VLOOKUP(C19,'MASTER Name List'!$B$3:$M$186,2,FALSE) -> 黄得财 | E19: 45809 | F19: 45992 | G19: Jun-Dec'25 | H19: =DATEDIF(E19,F19,"M")+1 -> 7 | I19: 50 | J19: =$H19*$I19 -> 350 | M19: 3 | U19: 45809
A20: 45804 | B20: CHE 0001156 | C20: 103 | D20: =VLOOKUP(C20,'MASTER Name List'!$B$3:$M$186,2,FALSE) -> 林采諺 | E20: 45778 | F20: 45870 | G20: May-Aug'25 | H20: =DATEDIF(E20,F20,"M")+1 -> 4 | I20: 50 | J20: =$H20*$I20 -> 200 | M20: 3 | U20: 45839
A21: 45804 | B21: CHE 0001157 | C21: 131 | D21: =VLOOKUP(C21,'MASTER Name List'!$B$3:$M$186,2,FALSE) -> 王康芬 | E21: 45809 | F21: 45870 | G21: Jun-Aug'25 | H21: =DATEDIF(E21,F21,"M")+1 -> 3 | I21: 50 | J21: =$H21*$I21 -> 150 | M21: 3 | N21: =SUMIF(M:M,"3",J:J) -> 1000 | O21: 04.06.2025 | U21: 45870
D22: =VLOOKUP(C22,'MASTER Name List'!$B$3:$M$186,2,FALSE) -> #N/A | H22: =DATEDIF(E22,F22,"M")+1 -> 1 | I22: 50 | J22: =$H22*$I22 -> 50 | U22: 45901
D23: =VLOOKUP(C23,'MASTER Name List'!$B$3:$M$186,2,FALSE) -> #N/A | H23: =DATEDIF(E23,F23,"M")+1 -> 1 | I23: 50 | J23: =$H23*$I23 -> 50 | U23: 45931
U24: 45962
B25: BANK IN | U25: 45992
A26: 45778 | B26: CHE0001312 | C26: 145 | D26: =VLOOKUP(C26,'MASTER Name List'!$B$3:$M$186,2,FALSE) -> 许俊豪 | E26: 45778 | F26: 45870 | G26: May-Aug25 | H26: =DATEDIF(E26,F26,"M")+1 -> 4 | I26: 50 | L26: =$H26*$I26 -> 200 | O26: Book No.127 | P26: BT | Q26: Khor Chun Hoe | T26: #145 | U26: 46023
A27: 45779 | B27: CHE0001313 | C27: 116 | D27: =VLOOKUP(C27,'MASTER Name List'!$B$3:$M$186,2,FALSE) -> 李薇薇 | E27: 45778 | F27: 45778 | G27: 45778 | H27: =DATEDIF(E27,F27,"M")+1 -> 1 | I27: 50 | L27: =$H27*$I27 -> 50 | P27: BT | Q27: Lee Wei Wei | T27: #116 | U27: 46054
A28: 45754 | B28: CHE0001314 | C28: 102 | D28: =VLOOKUP(C28,'MASTER Name List'!$B$3:$M$186,2,FALSE) -> 戴川凤 | E28: 45717 | F28: 45748 | G28: Mar_Apr25 | H28: =DATEDIF(E28,F28,"M")+1 -> 2 | I28: 50 | L28: =$H28*$I28 -> 100 | P28: ATM | T28: #117 | U28: 46082
A29: 45779 | B29: CHE0001315 | C29: 117 | D29: =VLOOKUP(C29,'MASTER Name List'!$B$3:$M$186,2,FALSE) -> 张志文 | E29: 45778 | F29: 45778 | G29: 46143 | H29: =DATEDIF(E29,F29,"M")+1 -> 1 | I29: 50 | L29: =$H29*$I29 -> 50 | P29: BT | Q29: Lee Wei Wei / Chong Chee Wen | U29: 46113
A30: 45779 | B30: CHE0001316 | C30: 123 | D30: =VLOOKUP(C30,'MASTER Name List'!$B$3:$M$186,2,FALSE) -> 黄丽娟 | E30: 45778 | F30: 45809 | G30: May_Jun25 | H30: =DATEDIF(E30,F30,"M")+1 -> 2 | I30: 50 | L30: =$H30*$I30 -> 100 | P30: BT | Q30: Wong Lee Ken | S30: #123 | U30: 46143
A31: 45781 | B31: CHE0001317 | C31: 137 | D31: =VLOOKUP(C31,'MASTER Name List'!$B$3:$M$186,2,FALSE) -> 赖美珍 | E31: 45778 | F31: 45778 | G31: 45778 | H31: =DATEDIF(E31,F31,"M")+1 -> 1 | I31: 50 | L31: =$H31*$I31 -> 50 | P31: ATM | S31: #137 | U31: 46174
A32: 45781 | B32: CHE0001318 | C32: 68 | D32: =VLOOKUP(C32,'MASTER Name List'!$B$3:$M$186,2,FALSE) -> 沈观胜 | E32: 45748 | F32: 45809 | G32: Apr_Jun25 | H32: =DATEDIF(E32,F32,"M")+1 -> 3 | I32: 50 | L32: =$H32*$I32 -> 150 | P32: BT | Q32: Sim Kuan Seng | S32: #68 | U32: 46204
A33: 45782 | B33: CHE0001319 | C33: 104 | D33: =VLOOKUP(C33,'MASTER Name List'!$B$3:$M$186,2,FALSE) -> 连美丽 | E33: 45778 | F33: 45809 | G33: May_Jun25 | H33: =DATEDIF(E33,F33,"M")+1 -> 2 | I33: 50 | L33: =$H33*$I33 -> 100 | P33: BT | Q33: Lien Mei Li | S33: #104 | U33: 46235
A34: 45786 | B34: CHE0001320 | C34: 172 | D34: =VLOOKUP(C34,'MASTER Name List'!$B$3:$M$186,2,FALSE) -> 蔡均镅 | E34: 45778 | F34: 45809 | G34: May_Jun25 | H34: =DATEDIF(E34,F34,"M")+1 -> 2 | I34: 50 | L34: =$H34*$I34 -> 100 | P34: BT | Q34: Chua Jiun Mei | S34: #172 | U34: 46266
A35: 45787 | B35: CHE0001321 | C35: 24 | D35: =VLOOKUP(C35,'MASTER Name List'!$B$3:$M$186,2,FALSE) -> 陈淑心 | E35: 45748 | F35: 45809 | G35: Apr_Jun25 | H35: =DATEDIF(E35,F35,"M")+1 -> 3 | I35: 50 | L35: =$H35*$I35 -> 150 | P35: BT | Q35: Chan Sook Ling | S35: #24 | U35: 46296
A36: 45788 | B36: CHE0001322 | C36: 155 | D36: =VLOOKUP(C36,'MASTER Name List'!$B$3:$M$186,2,FALSE) -> 李宝珠 | E36: 45778 | F36: 45809 | G36: May_Jun25 | H36: =DATEDIF(E36,F36,"M")+1 -> 2 | I36: 50 | L36: =$H36*$I36 -> 100 | P36: BT | Q36: Lee Poh Choo | S36: #155 | U36: 46327
A37: 45789 | B37: CHE0001323 | C37: 175 | D37: =VLOOKUP(C37,'MASTER Name List'!$B$3:$M$186,2,FALSE) -> 洪鼎惟 | E37: 45778 | F37: 45778 | G37: 45778 | H37: =DATEDIF(E37,F37,"M")+1 -> 1 | I37: 50 | L37: =$H37*$I37 -> 50 | P37: BT | Q37: Hoon Teng Hui | S37: #175 | U37: 46357
A38: 45791 | B38: CHE0001324 | C38: 40 | D38: =VLOOKUP(C38,'MASTER Name List'!$B$3:$M$186,2,FALSE) -> 何梅歆 | E38: 46023 | F38: 46023 | G38: 46023 | H38: =DATEDIF(E38,F38,"M")+1 -> 1 | I38: 50 | L38: =$H38*$I38 -> 50 | P38: BT | Q38: Hoo Mei Sing | S38: #40 | U38: 46388
A39: 45796 | B39: CHE0001325 | C39: 70 | D39: =VLOOKUP(C39,'MASTER Name List'!$B$3:$M$186,2,FALSE) -> 李䘤帷 | E39: 45689 | F39: 45839 | G39: Feb_Jul25 | H39: =DATEDIF(E39,F39,"M")+1 -> 6 | I39: 50 | L39: =$H39*$I39 -> 300 | P39: BT | Q39: Lee Lai Kheng | S39: #70
D40: =VLOOKUP(C40,'MASTER Name List'!$B$3:$M$186,2,FALSE) -> #N/A | H40: =DATEDIF(E40,F40,"M")+1 -> 1 | I40: 50 | L40: =$H40*$I40 -> 50
D41: =VLOOKUP(C41,'MASTER Name List'!$B$3:$M$186,2,FALSE) -> #N/A | H41: =DATEDIF(E41,F41,"M")+1 -> 1 | I41: 50 | L41: =$H41*$I41 -> 50
D42: =VLOOKUP(C42,'MASTER Name List'!$B$3:$M$186,2,FALSE) -> #N/A | H42: =DATEDIF(E42,F42,"M")+1 -> 1 | I42: 50 | L42: =$H42*$I42 -> 50
D43: =VLOOKUP(C43,'MASTER Name List'!$B$3:$M$186,2,FALSE) -> #N/A | H43: =DATEDIF(E43,F43,"M")+1 -> 1 | I43: 50 | L43: =$H43*$I43 -> 50
...

Sheet Jun-25
AG4: 2025 年 6 月份 - HLB 05500129613
A5: 月费善款 收纳表/ Official Receipt Summary:
F6: 10 | G6: 11 | H6: 12 | I6: 1 | J6: 2 | K6: 3 | L6: 4 | M6: 5 | N6: 6 | O6: 7 | P6: 8 | Q6: 9 | R6: 10 | S6: 11 | T6: 12 | U6: 1 | V6: 2 | W6: 3 | AC6: 金额 Amount (RM) | AG6: ** CDM : Cash Deposit Machine
A7: 日期 Date | B7: 收据编号 Official Receipt No | C7: 月费号码 | D7: 捐款人 姓名 Name | E7: 赞助的月份 Payment for the month of | F7: 45566 | G7: 45597 | H7: 45627 | I7: JAN | J7: FEB | K7: MAR | L7: APR | M7: MAY | N7: JUN | O7: JUL | P7: AUG | Q7: SEP | R7: OCT | S7: NOV | T7: DEC | U7: 46023 | V7: 46054 | W7: 46082 | X7: 46113 | Y7: 46143 | Z7: 46174 | AA7: No.of Month | AB7: 月费 | AC7: 现款 Cash | AD7: 支票 Cheque | AE7: 网上银行转账 Online Bank Transfer | AF7: CDM SEQ | AG7: (CDM) Bank-in Amount | AH7: (CDM) Bank-in Date | AI7: 备注 Remark
AC8: RM | AD8: RM
A9: 45810 | B9: CHE 0001158 | C9: 178 | D9: =VLOOKUP(C9,'MASTER Name List'!$B$3:$M$186,2,FALSE) -> 颜美葒 | E9: Aug-Sep'25 | P9: X | Q9: X | AA9: =COUNTIF($F9:$W9,"X") & "" -> 2 | AB9: 50 | AC9: =COUNTIF($F9:$Z9,"X")*$AB9 -> 100 | AF9: 1 | AI9: OR Book # 124
A10: 45811 | B10: CHE 0001159 | C10: 4 | D10: =VLOOKUP(C10,'MASTER Name List'!$B$3:$M$186,2,FALSE) -> 邹运金 | E10: May-Jun'25 | N10: X | O10: X | AA10: =COUNTIF($F10:$W10,"X") & "" -> 2 | AB10: 50 | AC10: =COUNTIF($F10:$Z10,"X")*$AB10 -> 100 | AF10: 1
A11: 45812 | B11: CHE 0001160 | C11: 177 | D11: =VLOOKUP(C11,'MASTER Name List'!$B$3:$M$186,2,FALSE) -> 陈桂香 | E11: Jul-Dec'25 | O11: X | P11: X | Q11: X | R11: X | S11: X | T11: X | AA11: =COUNTIF($F11:$W11,"X") & "" -> 6 | AB11: 50 | AC11: =COUNTIF($F11:$Z11,"X")*$AB11 -> 300 | AF11: 1
A12: 45813 | B12: CHE 0001161 | C12: 226 | D12: =VLOOKUP(C12,'MASTER Name List'!$B$3:$M$186,2,FALSE) -> 锺镒壕 | E12: Aug-Jun'25 | L12: X | M12: X | N12: X | AA12: =COUNTIF($F12:$W12,"X") & "" -> 3 | AB12: 50 | AC12: =COUNTIF($F12:$Z12,"X")*$AB12 -> 150 | AF12: 1 | AG12: =SUMIF(AF:AF,"1",AC:AC) -> 650 | AH12: 10.06.2025
A13: 45816 | B13: CHE 0001162 | C13: 114 | D13: =VLOOKUP(C13,'MASTER Name List'!$B$3:$M$186,2,FALSE) -> 刁修淋 | E13: May-Aug25 | M13: X | N13: X | O13: X | P13: X | AA13: =COUNTIF($F13:$W13,"X") & "" -> 4 | AB13: 50 | AC13: =COUNTIF($F13:$Z13,"X")*$AB13 -> 200 | AF13: 2
A14: 45818 | B14: CHE 0001163 | C14: 23 | D14: =VLOOKUP(C14,'MASTER Name List'!$B$3:$M$186,2,FALSE) -> 罗彩瑛 | E14: Jul-Aug25 | O14: X | P14: X | AA14: =COUNTIF($F14:$W14,"X") & "" -> 2 | AB14: 50 | AC14: =COUNTIF($F14:$Z14,"X")*$AB14 -> 100 | AF14: 2
A15: 45818 | B15: CHE 0001164 | C15: 96 | D15: =VLOOKUP(C15,'MASTER Name List'!$B$3:$M$186,2,FALSE) -> 余丽苹 | E15: Jul-Dec25 | O15: X | P15: X | Q15: X | R15: X | S15: X | T15: X | AA15: =COUNTIF($F15:$W15,"X") & "" -> 6 | AB15: 50 | AC15: =COUNTIF($F15:$Z15,"X")*$AB15 -> 300 | AF15: 2
A16: 45818 | B16: CHE 0001165 | C16: 106 | D16: =VLOOKUP(C16,'MASTER Name List'!$B$3:$M$186,2,FALSE) -> 文渼媄 | E16: Jul-Dec25 | O16: X | P16: X | Q16: X | R16: X | S16: X | T16: X | AA16: =COUNTIF($F16:$W16,"X") & "" -> 6 | AB16: 50 | AC16: =COUNTIF($F16:$Z16,"X")*$AB16 -> 300 | AF16: 2
A17: 45818 | B17: CHE 0001166 | C17: 228 | D17: =VLOOKUP(C17,'MASTER Name List'!$B$3:$M$186,2,FALSE) -> 黄诗霞 | E17: Jul25-Jun26 | O17: X | P17: X | Q17: X | R17: X | S17: X | T17: X | U17: X | V17: X | W17: X | X17: X | Y17: X | Z17: X | AA17: =COUNTIF($F17:$W17,"X") & "" -> 9 | AB17: 50 | AC17: =COUNTIF($F17:$Z17,"X")*$AB17 -> 600 | AF17: 2
A18: 45823 | B18: CHE 0001167 | C18: 42 | D18: =VLOOKUP(C18,'MASTER Name List'!$B$3:$M$186,2,FALSE) -> 李俐赪 | E18: Jul-Dec25 | O18: X | P18: X | Q18: X | R18: X | S18: X | T18: X | AA18: =COUNTIF($F18:$W18,"X") & "" -> 6 | AB18: 50 | AC18: =COUNTIF($F18:$Z18,"X")*$AB18 -> 300 | AF18: 2 | AG18: =SUMIF(AF:AF,"2",AC:AC) -> 1800 | AH18: 23.06.2025
A19: 45830 | B19: CHE 0001168 | C19: 170 | D19: =VLOOKUP(C19,'MASTER Name List'!$B$3:$M$186,2,FALSE) -> 陈柔霓 | E19: May-Jun'25 | M19: X | N19: X | AA19: =COUNTIF($F19:$W19,"X") & "" -> 2 | AB19: 50 | AC19: =COUNTIF($F19:$Z19,"X")*$AB19 -> 100 | AF19: 3
A20: 45832 | B20: CHE 0001169 | C20: 132 | D20: =VLOOKUP(C20,'MASTER Name List'!$B$3:$M$186,2,FALSE) -> 陈杍䍿 | E20: Jun-Aug25 | N20: X | O20: X | P20: X | AA20: =COUNTIF($F20:$W20,"X") & "" -> 3 | AB20: 50 | AC20: =COUNTIF($F20:$Z20,"X")*$AB20 -> 150 | AF20: 3
A21: 45833 | B21: CHE 0001170 | C21: 99 | D21: =VLOOKUP(C21,'MASTER Name List'!$B$3:$M$186,2,FALSE) -> 吴毓遴 | E21: May-Dec25 | M21: X | N21: X | O21: X | P21: X | Q21: X | R21: X | S21: X | T21: X | AA21: =COUNTIF($F21:$W21,"X") & "" -> 8 | AB21: 50 | AC21: =COUNTIF($F21:$Z21,"X")*$AB21 -> 400 | AF21: 3
A22: 45834 | B22: CHE 0001171 | C22: 62 | D22: =VLOOKUP(C22,'MASTER Name List'!$B$3:$M$186,2,FALSE) -> 叶淑芳 | E22: Jul-Dec25 | O22: X | P22: X | Q22: X | R22: X | S22: X | T22: X | AA22: =COUNTIF($F22:$W22,"X") & "" -> 6 | AB22: 50 | AC22: =COUNTIF($F22:$Z22,"X")*$AB22 -> 300 | AF22: 3 | AG22: =SUMIF(AF:AF,"3",AC:AC) -> 950 | AH22: 01.07.2025
A23: 45838 | B23: CHE 0001172 | C23: 214 | D23: =VLOOKUP(C23,'MASTER Name List'!$B$3:$M$186,2,FALSE) -> 苏淑禛 | E23: Jul-Sep25 | N23: X | O23: X | P23: X | AA23: =COUNTIF($F23:$W23,"X") & "" -> 3 | AB23: 50 | AC23: =COUNTIF($F23:$Z23,"X")*$AB23 -> 150 | AF23: 4 | AG23: =SUMIF(AF:AF,"4",AC:AC) -> 150 | AH23: 07.07.2025
D24: =VLOOKUP(C24,'MASTER Name List'!$B$3:$M$186,2,FALSE) -> #N/A
B29: BANK IN
A30: 45810 | C30: 80 | D30: =VLOOKUP(C30,'MASTER Name List'!$B$3:$M$186,2,FALSE) -> 黄淑芬 | E30: 45809 | N30: X | AA30: =COUNTIF($F30:$W30,"X") & "" -> 1 | AB30: 50 | AE30: =COUNTIF($F30:$W30,"X")*$AB30 -> 50 | AI30: BT | AJ30: Wong Su Fong | AL30: #80
A31: 45810 | C31: 224 | D31: =VLOOKUP(C31,'MASTER Name List'!$B$3:$M$186,2,FALSE) -> 黄文勝 | E31: 45809 | N31: X | AA31: =COUNTIF($F31:$W31,"X") & "" -> 1 | AB31: 50 | AE31: =COUNTIF($F31:$W31,"X")*$AB31 -> 50 | AI31: BT | AJ31: Wong Su Fong | AL31: #224
A32: 45810 | C32: 116 | D32: =VLOOKUP(C32,'MASTER Name List'!$B$3:$M$186,2,FALSE) -> 李薇薇 | E32: 45809 | N32: X | AA32: =COUNTIF($F32:$W32,"X") & "" -> 1 | AB32: 50 | AE32: =COUNTIF($F32:$W32,"X")*$AB32 -> 50 | AI32: BT | AJ32: Lee Wei Wei
A33: 45810 | C33: 117 | D33: =VLOOKUP(C33,'MASTER Name List'!$B$3:$M$186,2,FALSE) -> 张志文 | E33: 45809 | N33: X | AA33: =COUNTIF($F33:$W33,"X") & "" -> 1 | AB33: 50 | AE33: =COUNTIF($F33:$W33,"X")*$AB33 -> 50 | AI33: BT | AJ33: Lee Wei Wei / Chong Chee Wen
A34: 45813 | C34: 52 | D34: =VLOOKUP(C34,'MASTER Name List'!$B$3:$M$186,2,FALSE) -> 陈宝蓉 | E34: May_Jun25 | M34: X | N34: X | AA34: =COUNTIF($F34:$W34,"X") & "" -> 2 | AB34: 50 | AE34: =COUNTIF($F34:$W34,"X")*$AB34 -> 100 | AI34: BT | AJ34: Tan Poh Yong | AL34: #52
A35: 45815 | C35: 162 | D35: =VLOOKUP(C35,'MASTER Name List'!$B$3:$M$186,2,FALSE) -> 方惠贤 | E35: Jul_Aug25 | O35: X | P35: X | AA35: =COUNTIF($F35:$W35,"X") & "" -> 2 | AB35: 50 | AE35: =COUNTIF($F35:$W35,"X")*$AB35 -> 100 | AI35: BT | AJ35: Fong Fui Ying | AL35: #162
A36: 45815 | C36: 102 | D36: =VLOOKUP(C36,'MASTER Name List'!$B$3:$M$186,2,FALSE) -> 戴川凤 | E36: May_Jun25 | M36: X | N36: X | AA36: =COUNTIF($F36:$W36,"X") & "" -> 2 | AB36: 50 | AE36: =COUNTIF($F36:$W36,"X")*$AB36 -> 100 | AI36: ATM | AL36: #102
A37: 45815 | C37: 137 | D37: =VLOOKUP(C37,'MASTER Name List'!$B$3:$M$186,2,FALSE) -> 赖美珍 | E37: 45809 | N37: X | AA37: =COUNTIF($F37:$W37,"X") & "" -> 1 | AB37: 50 | AE37: =COUNTIF($F37:$W37,"X")*$AB37 -> 50 | AI37: TouchNGo | AJ37: Lai Mei Chin | AL37: #137
A38: 45815 | C38: 48 | D38: =VLOOKUP(C38,'MASTER Name List'!$B$3:$M$186,2,FALSE) -> 叶鏸郧 | E38: Jan_Mar25 | I38: X | J38: X | K38: X | AA38: =COUNTIF($F38:$W38,"X") & "" -> 3 | AB38: 50 | AE38: =COUNTIF($F38:$W38,"X")*$AB38 -> 150 | AI38: BT | AJ38: Ms Yap Hui Yuen | AL38: #48
A39: 45816 | C39: 50 | D39: =VLOOKUP(C39,'MASTER Name List'!$B$3:$M$186,2,FALSE) -> 陈俊达 | E39: Jan_Dec25 | I39: X | J39: X | K39: X | L39: X | M39: X | N39: X | O39: X | P39: X | Q39: X | R39: X | S39: X | T39: X | AA39: =COUNTIF($F39:$W39,"X") & "" -> 12 | AB39: 50 | AE39: =COUNTIF($F39:$W39,"X")*$AB39 -> 600 | AI39: BT | AJ39: Chan Chun Tat | AL39: #50
A40: 45817 | C40: 40 | D40: =VLOOKUP(C40,'MASTER Name List'!$B$3:$M$186,2,FALSE) -> 何梅歆 | E40: Feb_Mar26 | V40: X | W40: X | AA40: =COUNTIF($F40:$W40,"X") & "" -> 2 | AB40: 50 | AE40: =COUNTIF($F40:$W40,"X")*$AB40 -> 100 | AI40: BT | AJ40: Hoo Mei Sing (Michelle) | AL40: #40
A41: 45833 | C41: 64 | D41: =VLOOKUP(C41,'MASTER Name List'!$B$3:$M$186,2,FALSE) -> 韦素枝 | E41: May_Aug25 | M41: X | N41: X | O41: X | P41: X | AA41: =COUNTIF($F41:$W41,"X") & "" -> 4 | AB41: 50 | AE41: =COUNTIF($F41:$W41,"X")*$AB41 -> 200 | AI41: BT | AJ41: Wai Soo Gei | AL41: #64
D42: =VLOOKUP(C42,'MASTER Name List'!$B$3:$M$186,2,FALSE) -> #N/A | AA42: =COUNTIF($F42:$W42,"X") & "" -> 0 | AB42: 50 | AE42: =COUNTIF($F42:$W42,"X")*$AB42 -> 0
D43: =VLOOKUP(C43,'MASTER Name List'!$B$3:$M$186,2,FALSE) -> #N/A | AA43: =COUNTIF($F43:$W43,"X") & "" -> 0 | AB43: 50 | AE43: =COUNTIF($F43:$W43,"X")*$AB43 -> 0
