Workbook

Sheet Sheet1
A1: 日期 Date | B1: 收据编号 Official Receipt No | C1: 编号 No/ | D1: 捐款人 姓名 Name | E1: START MONTH | F1: END MONTH | G1: No/ of Mth | H1: Total Amt | K1: CHE MEMBER | L1: Status | M1: 会员编号 | N1: 姓名 | O1: Total Payment | P1: Start Month | Q1: End Month
A2: 45644 | B2: CHE 0001056 | C2: 3 | D2: Anna Justina | E2: 45658 | F2: 45689 | G2: 2 | H2: 100 | K2: =IF(L2="CHE", COUNTIF($L$2:L2, "CHE"), "") -> 1 | L2: CHE | M2: 3 | N2: Anna Justina | O2: =SUMIF(C:C,M2,H:H) -> 750 | P2: =_xlfn.MINIFS($E:$E,$C:$C,$M2) -> 45658 | Q2: =_xlfn.MAXIFS($F:$F,$C:$C,$M2) -> 46082 | R2: =DATEDIF(P2,Q2,"M")+1 -> 15 | S2: =50*R2 -> 750
A3: 45686 | B3: CHE 0001091 | C3: 3 | D3: Anna Justina | E3: 45717 | F3: 45809 | G3: 4 | H3: 200 | K3: =IF(L3="CHE", COUNTIF($L$2:L3, "CHE"), "") -> 2 | L3: CHE | M3: 4 | N3: 邹运金 | O3: =SUMIF(C:C,M3,H:H) -> 900 | P3: =_xlfn.MINIFS($E:$E,$C:$C,$M3) -> 45658 | Q3: =_xlfn.MAXIFS($F:$F,$C:$C,$M3) -> 46174 | R3: =DATEDIF(P3,Q3,"M")+1 -> 18 | S3: =50*R3 -> 900
A4: 45854 | B4: CHE 0001183 | C4: 3 | D4: Anna Justina | E4: 45839 | F4: 45870 | G4: 2 | H4: 100 | K4: =IF(L4="CHE", COUNTIF($L$2:L4, "CHE"), "") | L4: STW | M4: 5 | N4: 林姵辰 | O4: =SUMIF(C:C,M4,H:H) -> 0 | P4: =_xlfn.MINIFS($E:$E,$C:$C,$M4) -> 0 | Q4: =_xlfn.MAXIFS($F:$F,$C:$C,$M4) -> 0 | R4: =DATEDIF(P4,Q4,"M")+1 -> 1 | S4: =50*R4 -> 50
A5: 45970 | B5: CHE 0001276 | C5: 3 | D5: Anna Justina | E5: 45901 | F5: 45931 | G5: 2 | H5: 100 | K5: =IF(L5="CHE", COUNTIF($L$2:L5, "CHE"), "") -> 3 | L5: CHE | M5: 6 | N5: 张婷奕 | O5: =SUMIF(C:C,M5,H:H) -> 1200 | P5: =_xlfn.MINIFS($E:$E,$C:$C,$M5) -> 45658 | Q5: =_xlfn.MAXIFS($F:$F,$C:$C,$M5) -> 46357 | R5: =DATEDIF(P5,Q5,"M")+1 -> 24 | S5: =50*R5 -> 1200
A6: 46084 | B6: CHE 0001445 | C6: 3 | D6: Anna Justina | E6: 45962 | F6: 45992 | G6: 2 | H6: 100 | K6: =IF(L6="CHE", COUNTIF($L$2:L6, "CHE"), "") -> 4 | L6: CHE | M6: 10 | N6: 吴添玉 | O6: =SUMIF(C:C,M6,H:H) -> 600 | P6: =_xlfn.MINIFS($E:$E,$C:$C,$M6) -> 46023 | Q6: =_xlfn.MAXIFS($F:$F,$C:$C,$M6) -> 46357 | R6: =DATEDIF(P6,Q6,"M")+1 -> 12 | S6: =50*R6 -> 600
A7: 46096 | B7: CHE 0001449 | C7: 3 | D7: Anna Justina | E7: 46023 | F7: 46054 | G7: 2 | H7: 100 | K7: =IF(L7="CHE", COUNTIF($L$2:L7, "CHE"), "") -> 5 | L7: CHE | M7: 11 | N7: 方玉芬 | O7: =SUMIF(C:C,M7,H:H) -> 1200 | P7: =_xlfn.MINIFS($E:$E,$C:$C,$M7) -> 45658 | Q7: =_xlfn.MAXIFS($F:$F,$C:$C,$M7) -> 46357 | R7: =DATEDIF(P7,Q7,"M")+1 -> 24 | S7: =50*R7 -> 1200
A8: 46096 | B8: CHE 0001450 | C8: 3 | D8: Anna Justina | E8: 46082 | F8: 46082 | G8: 1 | H8: 50 | K8: =IF(L8="CHE", COUNTIF($L$2:L8, "CHE"), "") | L8: STW | M8: 12 | N8: 黄欣仪 | O8: =SUMIF(C:C,M8,H:H) -> 0 | P8: =_xlfn.MINIFS($E:$E,$C:$C,$M8) -> 0 | Q8: =_xlfn.MAXIFS($F:$F,$C:$C,$M8) -> 0 | R8: =DATEDIF(P8,Q8,"M")+1 -> 1 | S8: =50*R8 -> 50
A9: 45665 | B9: CHE 0001077 | C9: 4 | D9: 邹运金 | E9: 45658 | F9: 45689 | G9: 2 | H9: 100 | K9: =IF(L9="CHE", COUNTIF($L$2:L9, "CHE"), "") -> 6 | L9: CHE | M9: 13 | N9: 黄慧霞 | O9: =SUMIF(C:C,M9,H:H) -> 700 | P9: =_xlfn.MINIFS($E:$E,$C:$C,$M9) -> 45658 | Q9: =_xlfn.MAXIFS($F:$F,$C:$C,$M9) -> 46054 | R9: =DATEDIF(P9,Q9,"M")+1 -> 14 | S9: =50*R9 -> 700
A10: 45749 | B10: CHE 0001136 | C10: 4 | D10: 邹运金 | E10: 45717 | F10: 45748 | G10: 2 | H10: 100 | K10: =IF(L10="CHE", COUNTIF($L$2:L10, "CHE"), "") -> 7 | L10: CHE | M10: 14 | N10: 廖佳韵 | O10: =SUMIF(C:C,M10,H:H) -> 700 | P10: =_xlfn.MINIFS($E:$E,$C:$C,$M10) -> 45597 | Q10: =_xlfn.MAXIFS($F:$F,$C:$C,$M10) -> 45992 | R10: =DATEDIF(P10,Q10,"M")+1 -> 14 | S10: =50*R10 -> 700
A11: 45811 | B11: CHE 0001159 | C11: 4 | D11: 邹运金 | E11: 45778 | F11: 45809 | G11: 2 | H11: 100 | K11: =IF(L11="CHE", COUNTIF($L$2:L11, "CHE"), "") -> 8 | L11: CHE | M11: 17 | N11: 王婉娟 | O11: =SUMIF(C:C,M11,H:H) -> 300 | P11: =_xlfn.MINIFS($E:$E,$C:$C,$M11) -> 45658 | Q11: =_xlfn.MAXIFS($F:$F,$C:$C,$M11) -> 45809 | R11: =DATEDIF(P11,Q11,"M")+1 -> 6 | S11: =50*R11 -> 300
A12: 45840 | B12: CHE 0001174 | C12: 4 | D12: 邹运金 | E12: 45839 | F12: 45870 | G12: 2 | H12: 100 | K12: =IF(L12="CHE", COUNTIF($L$2:L12, "CHE"), "") | L12: 退 (Jan-26) | M12: 18 | N12: 江杰骏 | O12: =SUMIF(C:C,M12,H:H) -> 350 | P12: =_xlfn.MINIFS($E:$E,$C:$C,$M12) -> 45505 | Q12: =_xlfn.MAXIFS($F:$F,$C:$C,$M12) -> 45689 | R12: =DATEDIF(P12,Q12,"M")+1 -> 7 | S12: =50*R12 -> 350
A13: 45922 | B13: CHE 0001255 | C13: 4 | D13: 邹运金 | E13: 45901 | F13: 45992 | G13: 4 | H13: 200 | K13: =IF(L13="CHE", COUNTIF($L$2:L13, "CHE"), "") -> 9 | L13: CHE | M13: 19 | N13: 廖秋华 | O13: =SUMIF(C:C,M13,H:H) -> 900 | P13: =_xlfn.MINIFS($E:$E,$C:$C,$M13) -> 45658 | Q13: =_xlfn.MAXIFS($F:$F,$C:$C,$M13) -> 46174 | R13: =DATEDIF(P13,Q13,"M")+1 -> 18 | S13: =50*R13 -> 900
... A16: 45698 | B16: CHE0001223 | C16: 6 | D16: 张婷奕 | E16: 45658 | F16: 45992 | G16: 12 | H16: 600 | K16: =IF(L16="CHE", COUNTIF($L$2:L16, "CHE"), "") | L16: 退 (Jan-26) | M16: 24 | N16: 陈淑心 | O16: =SUMIF(C:C,M16,H:H) -> 750 | P16: =_xlfn.MINIFS($E:$E,$C:$C,$M16) -> 45566 | Q16: =_xlfn.MAXIFS($F:$F,$C:$C,$M16) -> 45992 | R16: =DATEDIF(P16,Q16,"M")+1 -> 15 | S16: =50*R16 -> 750
A17: 46084 | C17: 6 | D17: 张婷奕 | E17: 46023 | F17: 46357 | G17: 12 | H17: 600 | K17: =IF(L17="CHE", COUNTIF($L$2:L17, "CHE"), "") -> 11 | L17: CHE | M17: 25 | N17: 何艺寿 | O17: =SUMIF(C:C,M17,H:H) -> 1200 | P17: =_xlfn.MINIFS($E:$E,$C:$C,$M17) -> 45658 | Q17: =_xlfn.MAXIFS($F:$F,$C:$C,$M17) -> 46357 | R17: =DATEDIF(P17,Q17,"M")+1 -> 24 | S17: =50*R17 -> 1200
A18: 46055 | B18: CHE 0001427 | C18: 10 | D18: 吴添玉 | E18: 46023 | F18: 46357 | G18: 12 | H18: 600 | K18: =IF(L18="CHE", COUNTIF($L$2:L18, "CHE"), "") | L18: STW | M18: 28 | N18: 陈莉莉 | O18: =SUMIF(C:C,M18,H:H) -> 0 | P18: =_xlfn.MINIFS($E:$E,$C:$C,$M18) -> 0 | Q18: =_xlfn.MAXIFS($F:$F,$C:$C,$M18) -> 0 | R18: =DATEDIF(P18,Q18,"M")+1 -> 1 | S18: =50*R18 -> 50
A19: 45686 | B19: CHE 0001094 | C19: 11 | D19: 方玉芬 | E19: 45658 | F19: 45992 | G19: 12 | H19: 600 | K19: =IF(L19="CHE", COUNTIF($L$2:L19, "CHE"), "") | L19: 退 (Jan-26) | M19: 29 | N19: 王万龄 | O19: =SUMIF(C:C,M19,H:H) -> 650 | P19: =_xlfn.MINIFS($E:$E,$C:$C,$M19) -> 45627 | Q19: =_xlfn.MAXIFS($F:$F,$C:$C,$M19) -> 45992 | R19: =DATEDIF(P19,Q19,"M")+1 -> 13 | S19: =50*R19 -> 650
A20: 46025 | B20: CHE 0001404 | C20: 11 | D20: 方玉芬 | E20: 46023 | F20: 46357 | G20: 12 | H20: 600 | K20: =IF(L20="CHE", COUNTIF($L$2:L20, "CHE"), "") | L20: CHE-X | M20: 32 | N20: 吴丽娟 | O20: =SUMIF(C:C,M20,H:H) -> 0 | P20: =_xlfn.MINIFS($E:$E,$C:$C,$M20) -> 0 | Q20: =_xlfn.MAXIFS($F:$F,$C:$C,$M20) -> 0 | R20: =DATEDIF(P20,Q20,"M")+1 -> 1 | S20: =50*R20 -> 50
A21: 45679 | B21: CHE0001211 | C21: 13 | D21: 黄慧霞 | E21: 45658 | F21: 45689 | G21: 2 | H21: 100 | K21: =IF(L21="CHE", COUNTIF($L$2:L21, "CHE"), "") -> 12 | L21: CHE | M21: 33 | N21: 房薇玲 | O21: =SUMIF(C:C,M21,H:H) -> 600 | P21: =_xlfn.MINIFS($E:$E,$C:$C,$M21) -> 45658 | Q21: =_xlfn.MAXIFS($F:$F,$C:$C,$M21) -> 45992 | R21: =DATEDIF(P21,Q21,"M")+1 -> 12 | S21: =50*R21 -> 600
A22: 45737 | B22: CHE0001245 | C22: 13 | D22: 黄慧霞 | E22: 45717 | F22: 45992 | G22: 10 | H22: 500 | K22: =IF(L22="CHE", COUNTIF($L$2:L22, "CHE"), "") | L22: STW | M22: 35 | N22: 王家宝 | O22: =SUMIF(C:C,M22,H:H) -> 0 | P22: =_xlfn.MINIFS($E:$E,$C:$C,$M22) -> 0 | Q22: =_xlfn.MAXIFS($F:$F,$C:$C,$M22) -> 0 | R22: =DATEDIF(P22,Q22,"M")+1 -> 1 | S22: =50*R22 -> 50
A23: 46074 | C23: 13 | D23: 黄慧霞 | E23: 46023 | F23: 46054 | G23: 2 | H23: 100 | K23: =IF(L23="CHE", COUNTIF($L$2:L23, "CHE"), "") -> 13 | L23: CHE | M23: 36 | N23: 钱淑娟 | O23: =SUMIF(C:C,M23,H:H) -> 1200 | P23: =_xlfn.MINIFS($E:$E,$C:$C,$M23) -> 45658 | Q23: =_xlfn.MAXIFS($F:$F,$C:$C,$M23) -> 46357 | R23: =DATEDIF(P23,Q23,"M")+1 -> 24 | S23: =50*R23 -> 1200
A24: 45717 | B24: CHE0001231 | C24: 14 | D24: 廖佳韵 | E24: 45597 | F24: 45748 | G24: 6 | H24: 300 | K24: =IF(L24="CHE", COUNTIF($L$2:L24, "CHE"), "") -> 14 | L24: CHE | M24: 40 | N24: 何梅歆 | O24: =SUMIF(C:C,M24,H:H) -> 1100 | P24: =_xlfn.MINIFS($E:$E,$C:$C,$M24) -> 45658 | Q24: =_xlfn.MAXIFS($F:$F,$C:$C,$M24) -> 46296 | R24: =DATEDIF(P24,Q24,"M")+1 -> 22 | S24: =50*R24 -> 1100
A25: 45964 | B25: CHE0001389 | C25: 14 | D25: 廖佳韵 | E25: 45778 | F25: 45992 | G25: 8 | H25: 400 | K25: =IF(L25="CHE", COUNTIF($L$2:L25, "CHE"), "") | L25: CHE-X | M25: 41 | N25: 曾宪康 | O25: =SUMIF(C:C,M25,H:H) -> 200 | P25: =_xlfn.MINIFS($E:$E,$C:$C,$M25) -> 45536 | Q25: =_xlfn.MAXIFS($F:$F,$C:$C,$M25) -> 45627 | R25: =DATEDIF(P25,Q25,"M")+1 -> 4 | S25: =50*R25 -> 200
A26: 45716 | B26: CHE0001230 | C26: 17 | D26: 王婉娟 | E26: 45658 | F26: 45809 | G26: 6 | H26: 300 | K26: =IF(L26="CHE", COUNTIF($L$2:L26, "CHE"), "") -> 15 | L26: CHE | M26: 42 | N26: 李俐赪 | O26: =SUMIF(C:C,M26,H:H) -> 900 | P26: =_xlfn.MINIFS($E:$E,$C:$C,$M26) -> 45658 | Q26: =_xlfn.MAXIFS($F:$F,$C:$C,$M26) -> 46174 | R26: =DATEDIF(P26,Q26,"M")+1 -> 18 | S26: =50*R26 -> 900
A27: 45641 | B27: CHE 0001055 | C27: 18 | D27: 江嘉峻 | E27: 45505 | F27: 45627 | G27: 5 | H27: 250 | K27: =IF(L27="CHE", COUNTIF($L$2:L27, "CHE"), "") -> 16 | L27: CHE | M27: 43 | N27: 林德成 | O27: =SUMIF(C:C,M27,H:H) -> 1000 | P27: =_xlfn.MINIFS($E:$E,$C:$C,$M27) -> 45658 | Q27: =_xlfn.MAXIFS($F:$F,$C:$C,$M27) -> 46235 | R27: =DATEDIF(P27,Q27,"M")+1 -> 20 | S27: =50*R27 -> 1000
A28: 45881 | B28: CHE 0001191 | C28: 18 | D28: 江杰骏 | E28: 45658 | F28: 45689 | G28: 2 | H28: 100 | K28: =IF(L28="CHE", COUNTIF($L$2:L28, "CHE"), "") | L28: STW | M28: 45 | N28: 林丽燕 | O28: =SUMIF(C:C,M28,H:H) -> 0 | P28: =_xlfn.MINIFS($E:$E,$C:$C,$M28) -> 0 | Q28: =_xlfn.MAXIFS($F:$F,$C:$C,$M28) -> 0 | R28: =DATEDIF(P28,Q28,"M")+1 -> 1 | S28: =50*R28 -> 50
A29: 45660 | B29: CHE 0001070 | C29: 19 | D29: 廖秋华 | E29: 45658 | F29: 45748 | G29: 4 | H29: 200 | K29: =IF(L29="CHE", COUNTIF($L$2:L29, "CHE"), "") -> 17 | L29: CHE | M29: 48 | N29: 叶鏸郧 | O29: =SUMIF(C:C,M29,H:H) -> 950 | P29: =_xlfn.MINIFS($E:$E,$C:$C,$M29) -> 45566 | Q29: =_xlfn.MAXIFS($F:$F,$C:$C,$M29) -> 46113 | R29: =DATEDIF(P29,Q29,"M")+1 -> 19 | S29: =50*R29 -> 950
A30: 45849 | B30: CHE 0001178 | C30: 19 | D30: 廖秋华 | E30: 45778 | F30: 45809 | G30: 2 | H30: 100 | K30: =IF(L30="CHE", COUNTIF($L$2:L30, "CHE"), "") -> 18 | L30: CHE | M30: 50 | N30: 陈俊达 | O30: =SUMIF(C:C,M30,H:H) -> 1200 | P30: =_xlfn.MINIFS($E:$E,$C:$C,$M30) -> 45658 | Q30: =_xlfn.MAXIFS($F:$F,$C:$C,$M30) -> 46357 | R30: =DATEDIF(P30,Q30,"M")+1 -> 24 | S30: =50*R30 -> 1200
A31: 45895 | B31: CHE 0001192 | C31: 19 | D31: 廖秋华 | E31: 45839 | F31: 45992 | G31: 6 | H31: 300 | K31: =IF(L31="CHE", COUNTIF($L$2:L31, "CHE"), "") -> 19 | L31: CHE | M31: 52 | N31: 陈宝蓉 | O31: =SUMIF(C:C,M31,H:H) -> 900 | P31: =_xlfn.MINIFS($E:$E,$C:$C,$M31) -> 45658 | Q31: =_xlfn.MAXIFS($F:$F,$C:$C,$M31) -> 46174 | R31: =DATEDIF(P31,Q31,"M")+1 -> 18 | S31: =50*R31 -> 900
A32: 46030 | B32: CHE 0001410 | C32: 19 | D32: 廖秋华 | E32: 46023 | F32: 46174 | G32: 6 | H32: 300 | K32: =IF(L32="CHE", COUNTIF($L$2:L32, "CHE"), "") -> 20 | L32: CHE | M32: 53 | N32: 张媄绮 | O32: =SUMIF(C:C,M32,H:H) -> 1200 | P32: =_xlfn.MINIFS($E:$E,$C:$C,$M32) -> 45658 | Q32: =_xlfn.MAXIFS($F:$F,$C:$C,$M32) -> 46357 | R32: =DATEDIF(P32,Q32,"M")+1 -> 24 | S32: =50*R32 -> 1200
A33: 45668 | B33: CHE 0001080 | C33: 23 | D33: 罗彩云 | E33: 45658 | F33: 45809 | G33: 6 | H33: 300 | K33: =IF(L33="CHE", COUNTIF($L$2:L33, "CHE"), "") -> 21 | L33: CHE | M33: 54 | N33: 黄丽玲 | O33: =SUMIF(C:C,M33,H:H) -> 800 | P33: =_xlfn.MINIFS($E:$E,$C:$C,$M33) -> 45658 | Q33: =_xlfn.MAXIFS($F:$F,$C:$C,$M33) -> 46113 | R33: =DATEDIF(P33,Q33,"M")+1 -> 16 | S33: =50*R33 -> 800
A34: 45818 | B34: CHE 0001163 | C34: 23 | D34: 罗彩瑛 | E34: 45839 | F34: 45870 | G34: 2 | H34: 100 | K34: =IF(L34="CHE", COUNTIF($L$2:L34, "CHE"), "") | L34: 退 (Apr-21) | M34: 56 | N34: 詹联明 | O34: =SUMIF(C:C,M34,H:H) -> 0 | P34: =_xlfn.MINIFS($E:$E,$C:$C,$M34) -> 0 | Q34: =_xlfn.MAXIFS($F:$F,$C:$C,$M34) -> 0 | R34: =DATEDIF(P34,Q34,"M")+1 -> 1 | S34: =50*R34 -> 50
A35: 45940 | B35: CHE 0001266 | C35: 23 | D35: 罗彩瑛 | E35: 45901 | F35: 45992 | G35: 4 | H35: 200 | K35: =IF(L35="CHE", COUNTIF($L$2:L35, "CHE"), "") -> 22 | L35: CHE | M35: 61 | N35: 黄素彬 | O35: =SUMIF(C:C,M35,H:H) -> 1200 | P35: =_xlfn.MINIFS($E:$E,$C:$C,$M35) -> 45839 | Q35: =_xlfn.MAXIFS($F:$F,$C:$C,$M35) -> 46539 | R35: =DATEDIF(P35,Q35,"M")+1 -> 24 | S35: =50*R35 -> 1200
... A59: 45817 | B59: CHE0001336 | C59: 40 | D59: 何梅歆 | E59: 46054 | F59: 46082 | G59: 2 | H59: 100 | K59: =IF(L59="CHE", COUNTIF($L$2:L59, "CHE"), "") -> 37 | L59: CHE | M59: 94 | N59: 余合福 | O59: =SUMIF(C:C,M59,H:H) -> 1050 | P59: =_xlfn.MINIFS($E:$E,$C:$C,$M59) -> 45839 | Q59: =_xlfn.MAXIFS($F:$F,$C:$C,$M59) -> 46539 | R59: =DATEDIF(P59,Q59,"M")+1 -> 24 | S59: =50*R59 -> 1200
A60: 46069 | C60: 40 | D60: 何梅歆 | E60: 46113 | F60: 46174 | G60: 3 | H60: 150 | K60: =IF(L60="CHE", COUNTIF($L$2:L60, "CHE"), "") | L60: 退 (Jan-21) | M60: 95 | N60: 刘黛娣 | O60: =SUMIF(C:C,M60,H:H) -> 0 | P60: =_xlfn.MINIFS($E:$E,$C:$C,$M60) -> 0 | Q60: =_xlfn.MAXIFS($F:$F,$C:$C,$M60) -> 0 | R60: =DATEDIF(P60,Q60,"M")+1 -> 1 | S60: =50*R60 -> 50
A61: 46094 | C61: 40 | D61: 何梅歆 | E61: 46204 | F61: 46235 | G61: 2 | H61: 100 | K61: =IF(L61="CHE", COUNTIF($L$2:L61, "CHE"), "") -> 38 | L61: CHE | M61: 96 | N61: 余丽苹 | O61: =SUMIF(C:C,M61,H:H) -> 900 | P61: =_xlfn.MINIFS($E:$E,$C:$C,$M61) -> 45658 | Q61: =_xlfn.MAXIFS($F:$F,$C:$C,$M61) -> 46174 | R61: =DATEDIF(P61,Q61,"M")+1 -> 18 | S61: =50*R61 -> 900
A62: 46120 | C62: 40 | D62: 何梅歆 | E62: 46266 | F62: 46266 | G62: 1 | H62: 50 | K62: =IF(L62="CHE", COUNTIF($L$2:L62, "CHE"), "") -> 39 | L62: CHE | M62: 97 | N62: 陈素秋 | O62: =SUMIF(C:C,M62,H:H) -> 1000 | P62: =_xlfn.MINIFS($E:$E,$C:$C,$M62) -> 45658 | Q62: =_xlfn.MAXIFS($F:$F,$C:$C,$M62) -> 46235 | R62: =DATEDIF(P62,Q62,"M")+1 -> 20 | S62: =50*R62 -> 1000
A63: 46149 | C63: 40 | D63: 何梅歆 | E63: 46296 | F63: 46296 | G63: 1 | H63: 50 | K63: =IF(L63="CHE", COUNTIF($L$2:L63, "CHE"), "") -> 40 | L63: CHE | M63: 99 | N63: 吴滟芳 | O63: =SUMIF(C:C,M63,H:H) -> 900 | P63: =_xlfn.MINIFS($E:$E,$C:$C,$M63) -> 45658 | Q63: =_xlfn.MAXIFS($F:$F,$C:$C,$M63) -> 46174 | R63: =DATEDIF(P63,Q63,"M")+1 -> 18 | S63: =50*R63 -> 900
A64: 45649 | B64: CHE0001035 | C64: 41 | D64: 曾宪康 | E64: 45536 | F64: 45627 | G64: 4 | H64: 200 | K64: =IF(L64="CHE", COUNTIF($L$2:L64, "CHE"), "") | L64: CHE-X | M64: 100 | N64: 温媜帏 | O64: =SUMIF(C:C,M64,H:H) -> 300 | P64: =_xlfn.MINIFS($E:$E,$C:$C,$M64) -> 45474 | Q64: =_xlfn.MAXIFS($F:$F,$C:$C,$M64) -> 45627 | R64: =DATEDIF(P64,Q64,"M")+1 -> 6 | S64: =50*R64 -> 300
A65: 45669 | B65: CHE 0001082 | C65: 42 | D65: 李俐祯 | E65: 45658 | F65: 45809 | G65: 6 | H65: 300 | K65: =IF(L65="CHE", COUNTIF($L$2:L65, "CHE"), "") | L65: STW | M65: 101 | N65: 刘千凤 | O65: =SUMIF(C:C,M65,H:H) -> 0 | P65: =_xlfn.MINIFS($E:$E,$C:$C,$M65) -> 0 | Q65: =_xlfn.MAXIFS($F:$F,$C:$C,$M65) -> 0 | R65: =DATEDIF(P65,Q65,"M")+1 -> 1 | S65: =50*R65 -> 50
...

Sheet Sheet3
B2: No | C2: Donator | D2: START MONTH | E2: END MONTH | F2: No/ of Mth | G2: Total Amt
B3: 3 | C3: Alice | D3: 45658 | E3: 45689 | F3: 2 | G3: 100
B4: 3 | C4: Alice | D4: 45839 | E4: 45870 | F4: 2 | G4: 100
B5: 3 | C5: Alice | D5: 45717 | E5: 45809 | F5: 4 | G5: 200
B6: 4 | C6: Emily | D6: 45658 | E6: 45689 | F6: 2 | G6: 100
B7: 4 | C7: Emily | D7: 45778 | E7: 45809 | F7: 2 | G7: 100
B8: 4 | C8: Emily | D8: 45839 | E8: 45870 | F8: 2 | G8: 100

Sheet Sheet2
A1: 编号 | B1: 姓名
A2: 3 | B2: Anna Justina | C2: =SUMIF(Sheet1!$C:$C,Sheet2!A2,Sheet1!$H:$H) -> 750
A3: 4 | B3: 邹运金 | C3: =SUMIF(Sheet1!$C:$C,Sheet2!A3,Sheet1!$H:$H) -> 900
A4: 5 | B4: 林姵辰 | C4: =SUMIF(Sheet1!$C:$C,Sheet2!A4,Sheet1!$H:$H) -> 0
A5: 6 | B5: 张婷奕 | C5: =SUMIF(Sheet1!$C:$C,Sheet2!A5,Sheet1!$H:$H) -> 1200
A6: 10 | B6: 吴添玉 | C6: =SUMIF(Sheet1!$C:$C,Sheet2!A6,Sheet1!$H:$H) -> 600
A7: 11 | B7: 方玉芬 | C7: =SUMIF(Sheet1!$C:$C,Sheet2!A7,Sheet1!$H:$H) -> 1200
A8: 12 | B8: 黄欣仪 | C8: =SUMIF(Sheet1!$C:$C,Sheet2!A8,Sheet1!$H:$H) -> 0
A9: 13 | B9: 黄慧霞 | C9: =SUMIF(Sheet1!$C:$C,Sheet2!A9,Sheet1!$H:$H) -> 700
A10: 14 | B10: 廖佳韵 | C10: =SUMIF(Sheet1!$C:$C,Sheet2!A10,Sheet1!$H:$H) -> 700
A11: 17 | B11: 王婉娟 | C11: =SUMIF(Sheet1!$C:$C,Sheet2!A11,Sheet1!$H:$H) -> 300
A12: 18 | B12: 江杰骏 | C12: =SUMIF(Sheet1!$C:$C,Sheet2!A12,Sheet1!$H:$H) -> 350
A13: 19 | B13: 廖秋华 | C13: =SUMIF(Sheet1!$C:$C,Sheet2!A13,Sheet1!$H:$H) -> 900
... A179: 229 | B179: 陈丽珍 | C179: =SUMIF(Sheet1!$C:$C,Sheet2!A179,Sheet1!$H:$H) -> 900
